Workbook

Sheet 총괄
A1: 학과 | B1: 분반 | C1: 학번 | D1: 이름 | E1: 전화번호 | F1: 이메일 | G1: W07_Q01_응답 | H1: W07_Q02_응답 | I1: W07_Q03_응답 | J1: W07_Q04_응답 | K1: W07_Q05_응답 | L1: W07_Q06_응답 | M1: W07_Q07_응답 | N1: W07_Q08_응답 | O1: W07_Q09_응답 | P1: W07_Q10_응답 | Q1: W07 | R1: W08_Q01_응답 | S1: W08_Q02_응답 | T1: W08_Q03_응답 | U1: W08_Q04_응답 | V1: W08_Q05_응답 | W1: W08_Q06_응답 | X1: W08_Q07_응답 | Y1: W08_Q08_응답 | Z1: W08_Q09_응답 | AA1: W08_Q10_응답 | AB1: W08 | AC1: W09_Q01_응답 | AD1: W09_Q02_응답 | AE1: W09_Q03_응답 | AF1: W09_Q04_응답 | AG1: W09_Q05_응답 | AH1: W09_Q06_응답 | AI1: W09_Q07_응답 | AJ1: W09_Q08_응답 | AK1: W09_Q09_응답 | AL1: W09_Q10_응답 | AM1: W09 | AN1: W10_Q01_응답 | AO1: W10_Q02_응답 | AP1: W10_Q03_응답 | AQ1: W10_Q04_응답 | AR1: W10_Q05_응답 | AS1: W10_Q06_응답 | AT1: W10_Q07_응답 | AU1: W10_Q08_응답 | AV1: W10_Q09_응답 | AW1: W10_Q10_응답 | AX1: W10 | AY1: W11_Q01_응답 | AZ1: W11_Q02_응답 | BA1: W11_Q03_응답 | BB1: W11_Q04_응답 | BC1: W11_Q05_응답 | BD1: W11_Q06_응답 | BE1: W11_Q07_응답 | BF1: W11_Q08_응답 | BG1: W11_Q09_응답 | BH1: W11_Q10_응답 | BI1: W11 | BJ1: 퀴즈합계 | BK1: 퀴즈응답수 | BL1: 퀴즈점수(30) | BM1: 출석점수(30) | BN1: 중간고사(20) | BO1: 기말고사(20) | BP1: 총점(100) | BQ1: 석차(분반) | BR1: 평점 | BS1: 결석수 | BT1: 비고
A2: 경영학부 경영학전공 | B2: 1 | C2: 20220034 | D2: 양곤 | E2: 010-5847-5169 | F2: 3201743705@qq.com | R2: BPR | S2: 遵循日常运营的正式化和标准化程序。 | T2: 企业间流程 | U2: 相同数据在多个部门重复存储，导致不一致。 | V2: 引入企业信息系统（EIS） | W2: 减少不必要的审批环节，从而最大限度地减少时间和资源。 | X2: 整合管理与客户的所有互动，最大限度地提高客户终身价值。 | Y2: 将业务运营整合到一个单一且一致的计算平台。 | Z2: O | AA2: O | AB2: =10*SUMPRODUCT(--(R2:AA2<>""),--(((R2:AA2=정답표!$C$4:$L$4)+(R2:AA2=정답표!$C$5:$L$5))>0)) -> 100 | AC2: 硬件、软件、数据、流程、人员 | AD2: 组织战略决定价值链，价值链决定业务流程，业务流程决定 SMIS 需求。 | AE2: 增加物质资本 | AF2: 直接销售用户数据：通过直接销售用户个人数据获取主要收入。 | AG2: 创新 (Innovation) | AH2: 指通过电子邮件、消息应用等难以追踪的渠道进行的社交分享区域，企业应在此处关注建立信任。 | AI2: 基于兴趣形成，一个用户可以同时属于多个社区。 | AJ2: 财务与会计 | AK2: O | AL2: O | AM2: =10*SUMPRODUCT(--(AC2:AL2<>""),--(((AC2:AL2=정답표!$C$6:$L$6)+(AC2:AL2=정답표!$C$7:$L$7))>0)) -> 100 | AY2: 支持IT技术以实现组织目标，并将其与经营目标相结合。 | AZ2: 有效连接信息系统(IS)战略与企业经营战略。 | BA2: 根据组织的目标和优先顺序，综合考虑战略、预算和风险。 | BB2: 谁来做信息系统相关的决策，谁来承担责任？ | BC2: 综合考虑项目的战略适用性和实际可行性。 | BD2: 将组织的部分IT功能委托给外部专业公司执行。 | BE2: 安全威胁完全消除，信息安全得到加强。 | BF2: O | BG2: O | BH2: X | BI2: =10*SUMPRODUCT(--(AY2:BH2<>""),--(((AY2:BH2=정답표!$C$10:$L$10)+(AY2:BH2=정답표!$C$11:$L$11))>0)) -> 100 | BJ2: =SUM(Q2,AB2,AM2,AX2,BI2) -> 300 | BK2: =COUNT(Q2,AB2,AM2,AX2,BI2) -> 3 | BL2: =IF(QuizMatchTable[[#This Row],[분반]]=1, QuizMatchTable[[#This Row],[퀴즈합계]]/4 *0.3, QuizMatchTable[[#This Row],[퀴즈합계]]/5*0.3) -> 22.5 | BM2: 28 | BN2: 19.2 | BP2: =SUM(QuizMatchTable[[#This Row],[퀴즈점수(30)]],BM2,BN2,BO2) -> 69.7 | BQ2: =IF(OR(BP2="",BP2=0,BT2="결석초과"),"",COUNTIFS($B$2:$B$109,B2,$BP$2:$BP$109,">"&BP2)+1) -> 5 | BR2: A0 | BS2: 3
A3: 경영학부 경영학전공 | B3: 1 | C3: 20220036 | D3: 이가기 | E3: 010-2451-5770 | F3: keeeyo@163.com | R3: BPR | S3: 遵循日常运营的正式化和标准化程序。 | T3: 企业间流程 | U3: 相同数据在多个部门重复存储，导致不一致。 | V3: 引入企业信息系统（EIS） | W3: 减少不必要的审批环节，从而最大限度地减少时间和资源。 | X3: 整合管理与客户的所有互动，最大限度地提高客户终身价值。 | Y3: 将业务运营整合到一个单一且一致的计算平台。 | Z3: O | AA3: O | AB3: =10*SUMPRODUCT(--(R3:AA3<>""),--(((R3:AA3=정답표!$C$4:$L$4)+(R3:AA3=정답표!$C$5:$L$5))>0)) -> 100 | AY3: 支持IT技术以实现组织目标，并将其与经营目标相结合。 | AZ3: 有效连接信息系统(IS)战略与企业经营战略。 | BA3: 根据组织的目标和优先顺序，综合考虑战略、预算和风险。 | BB3: 谁来做信息系统相关的决策，谁来承担责任？ | BC3: 综合考虑项目的战略适用性和实际可行性。 | BD3: 将组织的部分IT功能委托给外部专业公司执行。 | BE3: 安全威胁完全消除，信息安全得到加强。 | BF3: O | BG3: O | BH3: X | BI3: =10*SUMPRODUCT(--(AY3:BH3<>""),--(((AY3:BH3=정답표!$C$10:$L$10)+(AY3:BH3=정답표!$C$11:$L$11))>0)) -> 100 | BJ3: =SUM(Q3,AB3,AM3,AX3,BI3) -> 200 | BK3: =COUNT(Q3,AB3,AM3,AX3,BI3) -> 2 | BL3: =IF(QuizMatchTable[[#This Row],[분반]]=1, QuizMatchTable[[#This Row],[퀴즈합계]]/4 *0.3, QuizMatchTable[[#This Row],[퀴즈합계]]/5*0.3) -> 15 | BM3: 26 | BN3: 19.2 | BP3: =SUM(QuizMatchTable[[#This Row],[퀴즈점수(30)]],BM3,BN3,BO3) -> 60.2 | BQ3: =IF(OR(BP3="",BP3=0,BT3="결석초과"),"",COUNTIFS($B$2:$B$109,B3,$BP$2:$BP$109,">"&BP3)+1) -> 14 | BR3: B0 | BS3: 6
A4: 경영학과 | B4: 1 | C4: 20230421 | D4: 주세남 | E4: 010-8356-9850 | F4: 2488676213@qq.com | R4: BPR | S4: 遵循日常运营的正式化和标准化程序。 | T4: 企业级流程 | U4: 相同数据在多个部门重复存储，导致不一致。 | V4: 引入企业信息系统（EIS） | W4: 减少不必要的审批环节，从而最大限度地减少时间和资源。 | X4: 整合管理与客户的所有互动，最大限度地提高客户终身价值。 | Y4: 将业务运营整合到一个单一且一致的计算平台。 | Z4: O | AA4: O | AB4: =10*SUMPRODUCT(--(R4:AA4<>""),--(((R4:AA4=정답표!$C$4:$L$4)+(R4:AA4=정답표!$C$5:$L$5))>0)) -> 90 | AC4: 硬件、软件、数据、流程、人员 | AD4: 组织战略决定价值链，价值链决定业务流程，业务流程决定 SMIS 需求。 | AE4: 增加物质资本 | AF4: 直接销售用户数据：通过直接销售用户个人数据获取主要收入。 | AG4: 创新 (Innovation) | AH4: 指通过电子邮件、消息应用等难以追踪的渠道进行的社交分享区域，企业应在此处关注建立信任。 | AI4: 基于兴趣形成，一个用户可以同时属于多个社区。 | AJ4: 财务与会计 | AK4: O | AL4: O | AM4: =10*SUMPRODUCT(--(AC4:AL4<>""),--(((AC4:AL4=정답표!$C$6:$L$6)+(AC4:AL4=정답표!$C$7:$L$7))>0)) -> 100 | AY4: 支持IT技术以实现组织目标，并将其与经营目标相结合。 | AZ4: 有效连接信息系统(IS)战略与企业经营战略。 | BA4: 根据组织的目标和优先顺序，综合考虑战略、预算和风险。 | BB4: 谁来做信息系统相关的决策，谁来承担责任？ | BC4: 综合考虑项目的战略适用性和实际可行性。 | BD4: 将组织的部分IT功能委托给外部专业公司执行。 | BE4: 安全威胁完全消除，信息安全得到加强。 | BF4: O | BG4: O | BH4: X | BI4: =10*SUMPRODUCT(--(AY4:BH4<>""),--(((AY4:BH4=정답표!$C$10:$L$10)+(AY4:BH4=정답표!$C$11:$L$11))>0)) -> 100 | BJ4: =SUM(Q4,AB4,AM4,AX4,BI4) -> 290 | BK4: =COUNT(Q4,AB4,AM4,AX4,BI4) -> 3 | BL4: =IF(QuizMatchTable[[#This Row],[분반]]=1, QuizMatchTable[[#This Row],[퀴즈합계]]/4 *0.3, QuizMatchTable[[#This Row],[퀴즈합계]]/5*0.3) -> 21.75 | BM4: 28 | BN4: 18.8 | BP4: =SUM(QuizMatchTable[[#This Row],[퀴즈점수(30)]],BM4,BN4,BO4) -> 68.55 | BQ4: =IF(OR(BP4="",BP4=0,BT4="결석초과"),"",COUNTIFS($B$2:$B$109,B4,$BP$2:$BP$109,">"&BP4)+1) -> 6 | BR4: A0 | BS4: 3
A5: 경영학과 | B5: 1 | C5: 20230422 | D5: 쩐응옥휘 | E5: 010-5727-3028 | F5: huytranngoc1201@gmail.com | G5: B. 피드백 및 반복 (反馈和迭代) | H5: D. 최소한의 비용과 시간 소모 (最低限度的成本和时间消耗) | I5: C. 운영적 의사결정 (运营性决策) | J5: C. 마케팅 전략 (营销策略) | K5: C. 문제해결 (问题解决) | L5: C. 착수 → 계획 → 실행 → 마무리 (启动 → 计划 → 执行 → 结束) | M5: A. 프로젝트 콘텐츠 (项目内容/产出物), B. 프로젝트 메타데이터 (项目元数据) | N5: B. 비동기적 소통 (Asynchronous Communication / 异步沟通) | O5: X (거짓/错) | P5: O (참/对) | Q5: =10*SUMPRODUCT(--(G5:P5<>""),--(((G5:P5=정답표!$C$2:$L$2)+(G5:P5=정답표!$C$3:$L$3))>0)) -> 100 | R5: BPR | S5: 일상적인 운영을 위한 공식적이고 표준화된 절차를 따릅니다. | T5: 기업 간 프로세스 | U5: 동일한 데이터가 여러 부서에 중복 저장되어 불일치가 발생합니다. | V5: 전사적 정보시스템(EIS) 도입 | W5: 불필요한 승인 단계를 축소하여 시간과 자원을 최소화합니다. | X5: 고객과의 모든 상호작용을 통합 관리하여 고객 평생 가치를 극대화하는 것입니다. | Y5: 비즈니스 운영을 단일하고 일관된 컴퓨팅 플랫폼에 통합하는 것입니다. | Z5: O | AA5: O | AB5: =10*SUMPRODUCT(--(R5:AA5<>""),--(((R5:AA5=정답표!$C$4:$L$4)+(R5:AA5=정답표!$C$5:$L$5))>0)) -> 100 | AC5: 하드웨어,소프트웨어,데이터,절차,사람 | AD5: 조직 전략이 가치 사슬을 결정하고, 가치 사슬은 비즈니스 프로세스를, 프로세스는 SMIS 요구 사항을 결정합니다. | AE5: 물적 자본 증대 | AF5: 사용자 데이터 직접 판매: 사용자의 개인 데이터를 직접 판매하여 주된 수익을 얻습니다. | AG5: 혁신 (Innovation) | AH5: 이메일, 메시징 앱 등 추적하기 어려운 채널을 통한 소셜 공유 영역을 의미하며, 비즈니스는 여기서 신뢰 구축에 주목해야 합니다. | AI5: 관심사 기반으로 형성되며, 한 명의 사용자가 여러 커뮤니티에 동시 소속될 수 있습니다. | AJ5: 제조 및 운영 | AK5: O | AL5: O | AM5: =10*SUMPRODUCT(--(AC5:AL5<>""),--(((AC5:AL5=정답표!$C$6:$L$6)+(AC5:AL5=정답표!$C$7:$L$7))>0)) -> 90 | AY5: 조직의 목표 달성을 위해 IT 기술을 지원하고 경영 목표와 연결한다. | AZ5: 정보시스템(IS) 전략과 기업의 경영전략을 효과적으로 연결한다. | BA5: 조직의 목표와 우선순위에 맞춰 전략, 예산, 위험을 함께 고려한다. | BB5: 정보시스템 관련 의사결정을 누가 하고 그에 대한 책임은 누가 지는가? | BC5: 프로젝트의 전략적 적합성과 실제 실행 가능성을 종합적으로 고려한다. | BD5: 조직의 일부 IT 기능을 외부 전문 업체에 위탁하여 수행하게 하는 것이다. | BE5: 보안 위협이 완전히 제거되어 정보 보안이 강화된다. | BF5: O | BG5: O | BH5: X | BI5: =10*SUMPRODUCT(--(AY5:BH5<>""),--(((AY5:BH5=정답표!$C$10:$L$10)+(AY5:BH5=정답표!$C$11:$L$11))>0)) -> 100 | BJ5: =SUM(Q5,AB5,AM5,AX5,BI5) -> 390 | BK5: =COUNT(Q5,AB5,AM5,AX5,BI5) -> 4 | BL5: =IF(QuizMatchTable[[#This Row],[분반]]=1, QuizMatchTable[[#This Row],[퀴즈합계]]/4 *0.3, QuizMatchTable[[#This Row],[퀴즈합계]]/5*0.3) -> 29.25 | BM5: 30 | BN5: 13.2 | BP5: =SUM(QuizMatchTable[[#This Row],[퀴즈점수(30)]],BM5,BN5,BO5) -> 72.45 | BQ5: =IF(OR(BP5="",BP5=0,BT5="결석초과"),"",COUNTIFS($B$2:$B$109,B5,$BP$2:$BP$109,">"&BP5)+1) -> 4 | BR5: A+ | BS5: 0
A6: 경영학과 | B6: 1 | C6: 20230474 | D6: 조동령 | E6: 010-7714-8195 | F6: zdy2002dd@163.com | G6: B. 피드백 및 반복 (反馈和迭代) | H6: D. 최소한의 비용과 시간 소모 (最低限度的成本和时间消耗) | I6: C. 운영적 의사결정 (运营性决策) | J6: C. 마케팅 전략 (营销策略) | K6: C. 문제해결 (问题解决) | L6: C. 착수 → 계획 → 실행 → 마무리 (启动 → 计划 → 执行 → 结束) | M6: A. 프로젝트 콘텐츠 (项目内容/产出物) | N6: B. 비동기적 소통 (Asynchronous Communication / 异步沟通) | O6: X (거짓/错) | P6: O (참/对) | Q6: =10*SUMPRODUCT(--(G6:P6<>""),--(((G6:P6=정답표!$C$2:$L$2)+(G6:P6=정답표!$C$3:$L$3))>0)) -> 90 | R6: BPR | S6: 遵循日常运营的正式化和标准化程序。 | T6: 企业间流程 | U6: 相同数据在多个部门重复存储，导致不一致。 | V6: 引入企业信息系统（EIS） | W6: 减少不必要的审批环节，从而最大限度地减少时间和资源。 | X6: 整合管理与客户的所有互动，最大限度地提高客户终身价值。 | Y6: 实现现有分离系统之间的数据共享和通信。 | Z6: O | AA6: O | AB6: =10*SUMPRODUCT(--(R6:AA6<>""),--(((R6:AA6=정답표!$C$4:$L$4)+(R6:AA6=정답표!$C$5:$L$5))>0)) -> 90 | AC6: 硬件、软件、数据、流程、人员 | AD6: 组织战略决定价值链，价值链决定业务流程，业务流程决定 SMIS 需求。 | AE6: 增加物质资本 | AF6: 直接销售用户数据：通过直接销售用户个人数据获取主要收入。 | AG6: 创新 (Innovation) | AH6: 指通过电子邮件、消息应用等难以追踪的渠道进行的社交分享区域，企业应在此处关注建立信任。 | AI6: 基于兴趣形成，一个用户可以同时属于多个社区。 | AJ6: 财务与会计 | AK6: O | AL6: X | AM6: =10*SUMPRODUCT(--(AC6:AL6<>""),--(((AC6:AL6=정답표!$C$6:$L$6)+(AC6:AL6=정답표!$C$7:$L$7))>0)) -> 90 | AY6: 支持IT技术以实现组织目标，并将其与经营目标相结合。 | AZ6: 有效连接信息系统(IS)战略与企业经营战略。 | BA6: 根据组织的目标和优先顺序，综合考虑战略、预算和风险。 | BB6: 谁来做信息系统相关的决策，谁来承担责任？ | BC6: 综合考虑项目的战略适用性和实际可行性。 | BD6: 将组织的部分IT功能委托给外部专业公司执行。 | BE6: 安全威胁完全消除，信息安全得到加强。 | BF6: O | BG6: O | BH6: X | BI6: =10*SUMPRODUCT(--(AY6:BH6<>""),--(((AY6:BH6=정답표!$C$10:$L$10)+(AY6:BH6=정답표!$C$11:$L$11))>0)) -> 100 | BJ6: =SUM(Q6,AB6,AM6,AX6,BI6) -> 370 | BK6: =COUNT(Q6,AB6,AM6,AX6,BI6) -> 4 | BL6: =IF(QuizMatchTable[[#This Row],[분반]]=1, QuizMatchTable[[#This Row],[퀴즈합계]]/4 *0.3, QuizMatchTable[[#This Row],[퀴즈합계]]/5*0.3) -> 27.75 | BM6: 30 | BN6: 16 | BP6: =SUM(QuizMatchTable[[#This Row],[퀴즈점수(30)]],BM6,BN6,BO6) -> 73.75 | BQ6: =IF(OR(BP6="",BP6=0,BT6="결석초과"),"",COUNTIFS($B$2:$B$109,B6,$BP$2:$BP$109,">"&BP6)+1) -> 3 | BR6: A+ | BS6: 0
A7: 경영학과 | B7: 1 | C7: 20240033 | D7: 양우철 | E7: 010-5781-9370 | F7: snowly2408620437@163.com | G7: B. 피드백 및 반복 (反馈和迭代) | H7: D. 최소한의 비용과 시간 소모 (最低限度的成本和时间消耗) | I7: C. 운영적 의사결정 (运营性决策) | J7: C. 마케팅 전략 (营销策略) | K7: C. 문제해결 (问题解决) | L7: C. 착수 → 계획 → 실행 → 마무리 (启动 → 计划 → 执行 → 结束) | M7: A. 프로젝트 콘텐츠 (项目内容/产出物), B. 프로젝트 메타데이터 (项目元数据) | N7: B. 비동기적 소통 (Asynchronous Communication / 异步沟通) | O7: X (거짓/错) | P7: O (참/对) | Q7: =10*SUMPRODUCT(--(G7:P7<>""),--(((G7:P7=정답표!$C$2:$L$2)+(G7:P7=정답표!$C$3:$L$3))>0)) -> 100 | R7: BPR | S7: 遵循日常运营的正式化和标准化程序。 | T7: 企业间流程 | U7: 相同数据在多个部门重复存储，导致不一致。 | V7: 引入企业信息系统（EIS） | W7: 减少不必要的审批环节，从而最大限度地减少时间和资源。 | X7: 整合管理与客户的所有互动，最大限度地提高客户终身价值。 | Y7: 将业务运营整合到一个单一且一致的计算平台。 | Z7: O | AA7: O | AB7: =10*SUMPRODUCT(--(R7:AA7<>""),--(((R7:AA7=정답표!$C$4:$L$4)+(R7:AA7=정답표!$C$5:$L$5))>0)) -> 100 | AC7: 硬件、软件、数据、流程、人员 | AD7: 组织战略决定价值链，价值链决定业务流程，业务流程决定 SMIS 需求。 | AE7: 增加物质资本 | AF7: 直接销售用户数据：通过直接销售用户个人数据获取主要收入。 | AG7: 创新 (Innovation) | AH7: 指通过电子邮件、消息应用等难以追踪的渠道进行的社交分享区域，企业应在此处关注建立信任。 | AI7: 基于兴趣形成，一个用户可以同时属于多个社区。 | AJ7: 财务与会计 | AK7: O | AL7: O | AM7: =10*SUMPRODUCT(--(AC7:AL7<>""),--(((AC7:AL7=정답표!$C$6:$L$6)+(AC7:AL7=정답표!$C$7:$L$7))>0)) -> 100 | AY7: 支持IT技术以实现组织目标，并将其与经营目标相结合。 | AZ7: 有效连接信息系统(IS)战略与企业经营战略。 | BA7: 根据组织的目标和优先顺序，综合考虑战略、预算和风险。 | BB7: 谁来做信息系统相关的决策，谁来承担责任？ | BC7: 综合考虑项目的战略适用性和实际可行性。 | BD7: 将组织的部分IT功能委托给外部专业公司执行。 | BE7: 安全威胁完全消除，信息安全得到加强。 | BF7: O | BG7: O | BH7: X | BI7: =10*SUMPRODUCT(--(AY7:BH7<>""),--(((AY7:BH7=정답표!$C$10:$L$10)+(AY7:BH7=정답표!$C$11:$L$11))>0)) -> 100 | BJ7: =SUM(Q7,AB7,AM7,AX7,BI7) -> 400 | BK7: =COUNT(Q7,AB7,AM7,AX7,BI7) -> 4 | BL7: =IF(QuizMatchTable[[#This Row],[분반]]=1, QuizMatchTable[[#This Row],[퀴즈합계]]/4 *0.3, QuizMatchTable[[#This Row],[퀴즈합계]]/5*0.3) -> 30 | BM7: 30 | BN7: 18.39 | BP7: =SUM(QuizMatchTable[[#This Row],[퀴즈점수(30)]],BM7,BN7,BO7) -> 78.39 | BQ7: =IF(OR(BP7="",BP7=0,BT7="결석초과"),"",COUNTIFS($B$2:$B$109,B7,$BP$2:$BP$109,">"&BP7)+1) -> 1 | BR7: A+ | BS7: 0
A8: 경영학과 | B8: 1 | C8: 20240665 | D8: 김재환 | E8: 010-3493-7130 | F8: kjhflg@hanmail.net | BL8: =IF(QuizMatchTable[[#This Row],[분반]]=1, QuizMatchTable[[#This Row],[퀴즈합계]]/4 *0.3, QuizMatchTable[[#This Row],[퀴즈합계]]/5*0.3) -> 0 | BM8: 22 | BN8: 18 | BP8: =SUM(QuizMatchTable[[#This Row],[퀴즈점수(30)]],BM8,BN8,BO8) -> 40 | BQ8: =IF(OR(BP8="",BP8=0,BT8="결석초과"),"",COUNTIFS($B$2:$B$109,B8,$BP$2:$BP$109,">"&BP8)+1) -> 19 | BR8: F | BS8: 12
A9: 경영학과 | B9: 1 | C9: 20240666 | D9: 김준환 | E9: 010-8602-1022 | BL9: =IF(QuizMatchTable[[#This Row],[분반]]=1, QuizMatchTable[[#This Row],[퀴즈합계]]/4 *0.3, QuizMatchTable[[#This Row],[퀴즈합계]]/5*0.3) -> 0 | BM9: 0 | BN9: 0 | BP9: =SUM(QuizMatchTable[[#This Row],[퀴즈점수(30)]],BM9,BN9,BO9) -> 0 | BQ9: =IF(OR(BP9="",BP9=0,BT9="결석초과"),"",COUNTIFS($B$2:$B$109,B9,$BP$2:$BP$109,">"&BP9)+1) | BR9: F | BS9: 36 | BT9: 결석초과
A10: 경영학과 | B10: 1 | C10: 20240667 | D10: 송진근 | E10: 010-2509-0173 | F10: song110746@naver.com | R10: BPR | S10: 조직의 변화에 따라 프로세스 구조가 신속하게 적응하고 변경됩니다. | T10: 구조적 프로세스 | U10: 각 부서의 시스템 개발 비용이 절감됩니다. | V10: 전사적 정보시스템(EIS) 도입 | W10: 불필요한 승인 단계를 축소하여 시간과 자원을 최소화합니다. | X10: 고객과의 모든 상호작용을 통합 관리하여 고객 평생 가치를 극대화하는 것입니다. | Y10: 특정 작업 그룹이나 단일 부서의 업무 프로세스를 자동화하는 것입니다. | Z10: O | AA10: O | AB10: =10*SUMPRODUCT(--(R10:AA10<>""),--(((R10:AA10=정답표!$C$4:$L$4)+(R10:AA10=정답표!$C$5:$L$5))>0)) -> 60 | AC10: 하드웨어,소프트웨어,데이터,절차,사람 | AD10: SMIS 요구 사항이 먼저 결정되고, 이는 가치 사슬과 조직 전략에 영향을 미칩니다. | AE10: 개인적 강화 | AF10: 사용자 데이터 직접 판매: 사용자의 개인 데이터를 직접 판매하여 주된 수익을 얻습니다. | AG10: 혁신 (Innovation) | AH10: 인공지능(AI)이 생성한 가짜 뉴스나 딥페이크 콘텐츠가 확산되는 소셜 미디어의 어두운 면을 지칭합니다. | AI10: 관심사 기반으로 형성되며, 한 명의 사용자가 여러 커뮤니티에 동시 소속될 수 있습니다. | AJ10: 재무 및 회계 | AK10: O | AL10: O | AM10: =10*SUMPRODUCT(--(AC10:AL10<>""),--(((AC10:AL10=정답표!$C$6:$L$6)+(AC10:AL10=정답표!$C$7:$L$7))>0)) -> 70 | AY10: 조직의 목표 달성을 위해 IT 기술을 지원하고 경영 목표와 연결한다. | AZ10: 정보시스템(IS) 전략과 기업의 경영전략을 효과적으로 연결한다. | BA10: 조직의 목표와 우선순위에 맞춰 전략, 예산, 위험을 함께 고려한다. | BB10: 정보시스템 관련 의사결정을 누가 하고 그에 대한 책임은 누가 지는가? | BC10: 프로젝트의 전략적 적합성과 실제 실행 가능성을 종합적으로 고려한다. | BD10: 조직의 일부 IT 기능을 외부 전문 업체에 위탁하여 수행하게 하는 것이다. | BE10: 예상보다 장기적인 관점에서 더 높은 비용이 발생할 수 있다. | BF10: O | BG10: O | BH10: X | BI10: =10*SUMPRODUCT(--(AY10:BH10<>""),--(((AY10:BH10=정답표!$C$10:$L$10)+(AY10:BH10=정답표!$C$11:$L$11))>0)) -> 90 | BJ10: =SUM(Q10,AB10,AM10,AX10,BI10) -> 220 | BK10: =COUNT(Q10,AB10,AM10,AX10,BI10) -> 3 | BL10: =IF(QuizMatchTable[[#This Row],[분반]]=1, QuizMatchTable[[#This Row],[퀴즈합계]]/4 *0.3, QuizMatchTable[[#This Row],[퀴즈합계]]/5*0.3) -> 16.5 | BM10: 30 | BN10: 5.2 | BP10: =SUM(QuizMatchTable[[#This Row],[퀴즈점수(30)]],BM10,BN10,BO10) -> 51.7 | BQ10: =IF(OR(BP10="",BP10=0,BT10="결석초과"),"",COUNTIFS($B$2:$B$109,B10,$BP$2:$BP$109,">"&BP10)+1) -> 18 | BR10: F | BS10: 0
A11: 경영학과 | B11: 1 | C11: 20240812 | D11: 응옌 티 쑤언 꾸인 | E11: 010-5948-6027 | F11: xquynh2706@gmail.com | R11: BPR | S11: 일상적인 운영을 위한 공식적이고 표준화된 절차를 따릅니다. | T11: 기업 간 프로세스 | U11: 동일한 데이터가 여러 부서에 중복 저장되어 불일치가 발생합니다. | V11: 전사적 정보시스템(EIS) 도입 | W11: 불필요한 승인 단계를 축소하여 시간과 자원을 최소화합니다. | X11: 고객과의 모든 상호작용을 통합 관리하여 고객 평생 가치를 극대화하는 것입니다. | Y11: 비즈니스 운영을 단일하고 일관된 컴퓨팅 플랫폼에 통합하는 것입니다. | Z11: O | AA11: O | AB11: =10*SUMPRODUCT(--(R11:AA11<>""),--(((R11:AA11=정답표!$C$4:$L$4)+(R11:AA11=정답표!$C$5:$L$5))>0)) -> 100 | AC11: 하드웨어,소프트웨어,커뮤니티,절차,사람 | AD11: 조직 전략이 가치 사슬을 결정하고, 가치 사슬은 비즈니스 프로세스를, 프로세스는 SMIS 요구 사항을 결정합니다. | AE11: 물적 자본 증대 | AF11: 사용자 데이터 직접 판매: 사용자의 개인 데이터를 직접 판매하여 주된 수익을 얻습니다. | AG11: 혁신 (Innovation) | AH11: 이메일, 메시징 앱 등 추적하기 어려운 채널을 통한 소셜 공유 영역을 의미하며, 비즈니스는 여기서 신뢰 구축에 주목해야 합니다. | AI11: 관심사 기반으로 형성되며, 한 명의 사용자가 여러 커뮤니티에 동시 소속될 수 있습니다. | AJ11: 재무 및 회계 | AK11: O | AL11: O | AM11: =10*SUMPRODUCT(--(AC11:AL11<>""),--(((AC11:AL11=정답표!$C$6:$L$6)+(AC11:AL11=정답표!$C$7:$L$7))>0)) -> 90 | AY11: 조직의 목표 달성을 위해 IT 기술을 지원하고 경영 목표와 연결한다. | AZ11: 정보시스템(IS) 전략과 기업의 경영전략을 효과적으로 연결한다. | BA11: 조직의 목표와 우선순위에 맞춰 전략, 예산, 위험을 함께 고려한다. | BB11: 정보시스템 관련 의사결정을 누가 하고 그에 대한 책임은 누가 지는가? | BC11: 프로젝트의 전략적 적합성과 실제 실행 가능성을 종합적으로 고려한다. | BD11: 조직의 일부 IT 기능을 외부 전문 업체에 위탁하여 수행하게 하는 것이다. | BE11: 보안 위협이 완전히 제거되어 정보 보안이 강화된다. | BF11: O | BG11: O | BH11: X | BI11: =10*SUMPRODUCT(--(AY11:BH11<>""),--(((AY11:BH11=정답표!$C$10:$L$10)+(AY11:BH11=정답표!$C$11:$L$11))>0)) -> 100 | BJ11: =SUM(Q11,AB11,AM11,AX11,BI11) -> 290 | BK11: =COUNT(Q11,AB11,AM11,AX11,BI11) -> 3 | BL11: =IF(QuizMatchTable[[#This Row],[분반]]=1, QuizMatchTable[[#This Row],[퀴즈합계]]/4 *0.3, QuizMatchTable[[#This Row],[퀴즈합계]]/5*0.3) -> 21.75 | BM11: 26 | BN11: 19.6 | BP11: =SUM(QuizMatchTable[[#This Row],[퀴즈점수(30)]],BM11,BN11,BO11) -> 67.35 | BQ11: =IF(OR(BP11="",BP11=0,BT11="결석초과"),"",COUNTIFS($B$2:$B$109,B11,$BP$2:$BP$109,">"&BP11)+1) -> 9 | BR11: B+ | BS11: 6
A12: 경영학과 | B12: 1 | C12: 20250935 | D12: 김가민 | E12: 010-4389-0603 | F12: kimgamin0603@gmail.com | AC12: 콘텐츠, 플랫폼, 네트워크,가치사슬,하드웨어 | AD12: 조직 전략이 가치 사슬을 결정하고, 가치 사슬은 비즈니스 프로세스를, 프로세스는 SMIS 요구 사항을 결정합니다. | AE12: 물적 자본 증대 | AF12: 프리미엄 (Freemium): 기본 서비스는 무료로 제공하고, 고급 기능이나 광고 제거에 비용을 부과합니다. | AG12: 투명성 (Disclosure) | AH12: 인공지능(AI)이 생성한 가짜 뉴스나 딥페이크 콘텐츠가 확산되는 소셜 미디어의 어두운 면을 지칭합니다. | AI12: 관심사 기반으로 형성되며, 한 명의 사용자가 여러 커뮤니티에 동시 소속될 수 있습니다. | AJ12: 고객 서비스 | AK12: X | AL12: O | AM12: =10*SUMPRODUCT(--(AC12:AL12<>""),--(((AC12:AL12=정답표!$C$6:$L$6)+(AC12:AL12=정답표!$C$7:$L$7))>0)) -> 40 | BJ12: =SUM(Q12,AB12,AM12,AX12,BI12) -> 40 | BK12: =COUNT(Q12,AB12,AM12,AX12,BI12) -> 1 | BL12: =IF(QuizMatchTable[[#This Row],[분반]]=1, QuizMatchTable[[#This Row],[퀴즈합계]]/4 *0.3, QuizMatchTable[[#This Row],[퀴즈합계]]/5*0.3) -> 3 | BM12: 24 | BN12: 8 | BP12: =SUM(QuizMatchTable[[#This Row],[퀴즈점수(30)]],BM12,BN12,BO12) -> 35 | BQ12: =IF(OR(BP12="",BP12=0,BT12="결석초과"),"",COUNTIFS($B$2:$B$109,B12,$BP$2:$BP$109,">"&BP12)+1) -> 20 | BR12: F | BS12: 9
A13: 경영학과 | B13: 1 | C13: 20250936 | D13: 김상민 | E13: 010-9868-3163 | F13: qlsdlsla4@gmail.com | G13: B. 피드백 및 반복 (反馈和迭代) | H13: D. 최소한의 비용과 시간 소모 (最低限度的成本和时间消耗) | I13: C. 운영적 의사결정 (运营性决策) | J13: C. 마케팅 전략 (营销策略) | K13: C. 문제해결 (问题解决) | L13: C. 착수 → 계획 → 실행 → 마무리 (启动 → 计划 → 执行 → 结束) | M13: A. 프로젝트 콘텐츠 (项目内容/产出物), B. 프로젝트 메타데이터 (项目元数据) | N13: B. 비동기적 소통 (Asynchronous Communication / 异步沟通) | O13: X (거짓/错) | P13: O (참/对) | Q13: =10*SUMPRODUCT(--(G13:P13<>""),--(((G13:P13=정답표!$C$2:$L$2)+(G13:P13=정답표!$C$3:$L$3))>0)) -> 100 | R13: BPR | S13: 일상적인 운영을 위한 공식적이고 표준화된 절차를 따릅니다. | T13: 기업 간 프로세스 | U13: 동일한 데이터가 여러 부서에 중복 저장되어 불일치가 발생합니다. | V13: 전사적 정보시스템(EIS) 도입 | W13: 불필요한 승인 단계를 축소하여 시간과 자원을 최소화합니다. | X13: 고객과의 모든 상호작용을 통합 관리하여 고객 평생 가치를 극대화하는 것입니다. | Y13: 비즈니스 운영을 단일하고 일관된 컴퓨팅 플랫폼에 통합하는 것입니다. | Z13: O | AA13: O | AB13: =10*SUMPRODUCT(--(R13:AA13<>""),--(((R13:AA13=정답표!$C$4:$L$4)+(R13:AA13=정답표!$C$5:$L$5))>0)) -> 100 | AY13: 조직의 목표 달성을 위해 IT 기술을 지원하고 경영 목표와 연결한다. | AZ13: 정보시스템(IS) 전략과 기업의 경영전략을 효과적으로 연결한다. | BA13: 조직의 목표와 우선순위에 맞춰 전략, 예산, 위험을 함께 고려한다. | BB13: 정보시스템 관련 의사결정을 누가 하고 그에 대한 책임은 누가 지는가? | BC13: 프로젝트의 전략적 적합성과 실제 실행 가능성을 종합적으로 고려한다. | BD13: 조직의 일부 IT 기능을 외부 전문 업체에 위탁하여 수행하게 하는 것이다. | BE13: 보안 위협이 완전히 제거되어 정보 보안이 강화된다. | BF13: O | BG13: O | BH13: X | BI13: =10*SUMPRODUCT(--(AY13:BH13<>""),--(((AY13:BH13=정답표!$C$10:$L$10)+(AY13:BH13=정답표!$C$11:$L$11))>0)) -> 100 | BJ13: =SUM(Q13,AB13,AM13,AX13,BI13) -> 300 | BK13: =COUNT(Q13,AB13,AM13,AX13,BI13) -> 3 | BL13: =IF(QuizMatchTable[[#This Row],[분반]]=1, QuizMatchTable[[#This Row],[퀴즈합계]]/4 *0.3, QuizMatchTable[[#This Row],[퀴즈합계]]/5*0.3) -> 22.5 | BM13: 26 | BN13: 20 | BP13: =SUM(QuizMatchTable[[#This Row],[퀴즈점수(30)]],BM13,BN13,BO13) -> 68.5 | BQ13: =IF(OR(BP13="",BP13=0,BT13="결석초과"),"",COUNTIFS($B$2:$B$109,B13,$BP$2:$BP$109,">"&BP13)+1) -> 7 | BR13: A0 | BS13: 6
A14: 경영학과 | B14: 1 | C14: 20250939 | D14: 이동윤 | E14: 010-3429-1571 | G14: B. 피드백 및 반복 (反馈和迭代) | H14: D. 최소한의 비용과 시간 소모 (最低限度的成本和时间消耗) | I14: C. 운영적 의사결정 (运营性决策) | J14: C. 마케팅 전략 (营销策略) | K14: C. 문제해결 (问题解决) | L14: C. 착수 → 계획 → 실행 → 마무리 (启动 → 计划 → 执行 → 结束) | M14: A. 프로젝트 콘텐츠 (项目内容/产出物), B. 프로젝트 메타데이터 (项目元数据) | N14: B. 비동기적 소통 (Asynchronous Communication / 异步沟通) | O14: X (거짓/错) | P14: O (참/对) | Q14: =10*SUMPRODUCT(--(G14:P14<>""),--(((G14:P14=정답표!$C$2:$L$2)+(G14:P14=정답표!$C$3:$L$3))>0)) -> 100 | R14: BPR | S14: 일상적인 운영을 위한 공식적이고 표준화된 절차를 따릅니다. | T14: 기업 간 프로세스 | U14: 동일한 데이터가 여러 부서에 중복 저장되어 불일치가 발생합니다. | V14: 전사적 정보시스템(EIS) 도입 | W14: 불필요한 승인 단계를 축소하여 시간과 자원을 최소화합니다. | X14: 고객과의 모든 상호작용을 통합 관리하여 고객 평생 가치를 극대화하는 것입니다. | Y14: 비즈니스 운영을 단일하고 일관된 컴퓨팅 플랫폼에 통합하는 것입니다. | Z14: O | AA14: O | AB14: =10*SUMPRODUCT(--(R14:AA14<>""),--(((R14:AA14=정답표!$C$4:$L$4)+(R14:AA14=정답표!$C$5:$L$5))>0)) -> 100 | AC14: 하드웨어,소프트웨어,커뮤니티,절차,사람 | AD14: 조직 전략이 가치 사슬을 결정하고, 가치 사슬은 비즈니스 프로세스를, 프로세스는 SMIS 요구 사항을 결정합니다. | AE14: 물적 자본 증대 | AF14: 사용자 데이터 직접 판매: 사용자의 개인 데이터를 직접 판매하여 주된 수익을 얻습니다. | AG14: 혁신 (Innovation) | AH14: 이메일, 메시징 앱 등 추적하기 어려운 채널을 통한 소셜 공유 영역을 의미하며, 비즈니스는 여기서 신뢰 구축에 주목해야 합니다. | AI14: 관심사 기반으로 형성되며, 한 명의 사용자가 여러 커뮤니티에 동시 소속될 수 있습니다. | AJ14: 재무 및 회계 | AK14: O | AL14: O | AM14: =10*SUMPRODUCT(--(AC14:AL14<>""),--(((AC14:AL14=정답표!$C$6:$L$6)+(AC14:AL14=정답표!$C$7:$L$7))>0)) -> 90 | BJ14: =SUM(Q14,AB14,AM14,AX14,BI14) -> 290 | BK14: =COUNT(Q14,AB14,AM14,AX14,BI14) -> 3 | BL14: =IF(QuizMatchTable[[#This Row],[분반]]=1, QuizMatchTable[[#This Row],[퀴즈합계]]/4 *0.3, QuizMatchTable[[#This Row],[퀴즈합계]]/5*0.3) -> 21.75 | BM14: 22 | BN14: 15.2 | BP14: =SUM(QuizMatchTable[[#This Row],[퀴즈점수(30)]],BM14,BN14,BO14) -> 58.95 | BQ14: =IF(OR(BP14="",BP14=0,BT14="결석초과"),"",COUNTIFS($B$2:$B$109,B14,$BP$2:$BP$109,">"&BP14)+1) -> 15 | BR14: B0 | BS14: 12
A15: 경영학과 | B15: 1 | C15: 20250940 | D15: 이성민 | E15: 010-2430-7874 | F15: zxcv4408@naver.com | G15: B. 피드백 및 반복 (反馈和迭代) | H15: C. 의미 있고 만족스러운 경험 (有意义且令人满意的经验) | I15: D. 비구조적 의사결정 (非结构性决策) | J15: A. 하드웨어 (硬件) | K15: C. 문제해결 (问题解决) | L15: B. 실행 → 계획 → 마무리 → 착수 (执行 → 计划 → 结束 → 启动) | M15: D. 팀원들의 개인정보 (团队成员的个人信息) | N15: A. 동기적 소통 (Synchronous Communication / 同步沟通) | O15: O (참/对) | P15: X (거짓/错) | Q15: =10*SUMPRODUCT(--(G15:P15<>""),--(((G15:P15=정답표!$C$2:$L$2)+(G15:P15=정답표!$C$3:$L$3))>0)) -> 20 | R15: CRM | S15: 일상적인 운영을 위한 공식적이고 표준화된 절차를 따릅니다. | T15: 구조적 프로세스 | U15: 각 부서의 시스템 개발 비용이 절감됩니다. | V15: 부서별 독립적인 시스템 유지 | W15: 신제품 출시 기간(TTM)을 단축하여 시장 경쟁력을 확보합니다. | X15: 공급망 파트너사와의 협업을 강화하여 물류 효율성을 높이는 것입니다. | Y15: 비즈니스 운영을 단일하고 일관된 컴퓨팅 플랫폼에 통합하는 것입니다. | Z15: O | AA15: X | AB15: =10*SUMPRODUCT(--(R15:AA15<>""),--(((R15:AA15=정답표!$C$4:$L$4)+(R15:AA15=정답표!$C$5:$L$5))>0)) -> 30 | AC15: 콘텐츠, 플랫폼, 네트워크,가치사슬,하드웨어 | AD15: SMIS 요구 사항이 먼저 결정되고, 이는 가치 사슬과 조직 전략에 영향을 미칩니다. | AE15: 물적 자본 증대 | AF15: 프리미엄 (Freemium): 기본 서비스는 무료로 제공하고, 고급 기능이나 광고 제거에 비용을 부과합니다. | AG15: 상식 (Common Sense) | AH15: 인공지능(AI)이 생성한 가짜 뉴스나 딥페이크 콘텐츠가 확산되는 소셜 미디어의 어두운 면을 지칭합니다. | AI15: 정보의 확산이 느리고, 주로 소수의 리더에 의해 통제되는 경향이 있습니다. | AJ15: 판매 및 마케팅 | AK15: O | AL15: X | AM15: =10*SUMPRODUCT(--(AC15:AL15<>""),--(((AC15:AL15=정답표!$C$6:$L$6)+(AC15:AL15=정답표!$C$7:$L$7))>0)) -> 20 | AY15: 기업의 회계 및 재무 자료만을 전문적으로 관리하고 보고한다. | AZ15: 기업의 영업 활동을 직접적으로 수행하고 성과를 창출한다. | BA15: 모든 업무 기능을 외부 전문 업체에 위탁하는 방안을 고려한다. | BB15: 정보시스템 관련 의사결정을 누가 하고 그에 대한 책임은 누가 지는가? | BC15: 프로젝트 이름의 인지도나 대외적인 홍보 효과를 중요하게 판단한다. | BD15: 조직의 일부 IT 기능을 외부 전문 업체에 위탁하여 수행하게 하는 것이다. | BE15: 보안 위협이 완전히 제거되어 정보 보안이 강화된다. | BF15: O | BG15: X | BH15: O | BI15: =10*SUMPRODUCT(--(AY15:BH15<>""),--(((AY15:BH15=정답표!$C$10:$L$10)+(AY15:BH15=정답표!$C$11:$L$11))>0)) -> 40 | BJ15: =SUM(Q15,AB15,AM15,AX15,BI15) -> 110 | BK15: =COUNT(Q15,AB15,AM15,AX15,BI15) -> 4 | BL15: =IF(QuizMatchTable[[#This Row],[분반]]=1, QuizMatchTable[[#This Row],[퀴즈합계]]/4 *0.3, QuizMatchTable[[#This Row],[퀴즈합계]]/5*0.3) -> 8.25 | BM15: 28 | BN15: 19.2 | BP15: =SUM(QuizMatchTable[[#This Row],[퀴즈점수(30)]],BM15,BN15,BO15) -> 55.45 | BQ15: =IF(OR(BP15="",BP15=0,BT15="결석초과"),"",COUNTIFS($B$2:$B$109,B15,$BP$2:$BP$109,">"&BP15)+1) -> 17 | BR15: F | BS15: 3
A16: 경영학과 | B16: 1 | C16: 20250944 | D16: 정유은 | E16: 010-3581-7557 | F16: yueun917@gmail.com | G16: B. 피드백 및 반복 (反馈和迭代) | H16: D. 최소한의 비용과 시간 소모 (最低限度的成本和时间消耗) | I16: C. 운영적 의사결정 (运营性决策) | J16: C. 마케팅 전략 (营销策略) | K16: C. 문제해결 (问题解决) | L16: C. 착수 → 계획 → 실행 → 마무리 (启动 → 计划 → 执行 → 结束) | M16: A. 프로젝트 콘텐츠 (项目内容/产出物), B. 프로젝트 메타데이터 (项目元数据) | N16: B. 비동기적 소통 (Asynchronous Communication / 异步沟通) | O16: X (거짓/错) | P16: O (참/对) | Q16: =10*SUMPRODUCT(--(G16:P16<>""),--(((G16:P16=정답표!$C$2:$L$2)+(G16:P16=정답표!$C$3:$L$3))>0)) -> 100 | R16: BPR | S16: 일상적인 운영을 위한 공식적이고 표준화된 절차를 따릅니다. | T16: 기업 간 프로세스 | U16: 동일한 데이터가 여러 부서에 중복 저장되어 불일치가 발생합니다. | V16: 전사적 정보시스템(EIS) 도입 | W16: 불필요한 승인 단계를 축소하여 시간과 자원을 최소화합니다. | X16: 고객과의 모든 상호작용을 통합 관리하여 고객 평생 가치를 극대화하는 것입니다. | Y16: 비즈니스 운영을 단일하고 일관된 컴퓨팅 플랫폼에 통합하는 것입니다. | Z16: O | AA16: O | AB16: =10*SUMPRODUCT(--(R16:AA16<>""),--(((R16:AA16=정답표!$C$4:$L$4)+(R16:AA16=정답표!$C$5:$L$5))>0)) -> 100 | AC16: 하드웨어,소프트웨어,데이터,절차,사람 | AD16: 조직 전략이 가치 사슬을 결정하고, 가치 사슬은 비즈니스 프로세스를, 프로세스는 SMIS 요구 사항을 결정합니다. | AE16: 물적 자본 증대 | AF16: 사용자 데이터 직접 판매: 사용자의 개인 데이터를 직접 판매하여 주된 수익을 얻습니다. | AG16: 혁신 (Innovation) | AH16: 이메일, 메시징 앱 등 추적하기 어려운 채널을 통한 소셜 공유 영역을 의미하며, 비즈니스는 여기서 신뢰 구축에 주목해야 합니다. | AI16: 관심사 기반으로 형성되며, 한 명의 사용자가 여러 커뮤니티에 동시 소속될 수 있습니다. | AJ16: 재무 및 회계 | AK16: O | AL16: O | AM16: =10*SUMPRODUCT(--(AC16:AL16<>""),--(((AC16:AL16=정답표!$C$6:$L$6)+(AC16:AL16=정답표!$C$7:$L$7))>0)) -> 100 | AY16: 조직의 목표 달성을 위해 IT 기술을 지원하고 경영 목표와 연결한다. | AZ16: 정보시스템(IS) 전략과 기업의 경영전략을 효과적으로 연결한다. | BA16: 조직의 목표와 우선순위에 맞춰 전략, 예산, 위험을 함께 고려한다. | BB16: 정보시스템 관련 의사결정을 누가 하고 그에 대한 책임은 누가 지는가? | BC16: 프로젝트의 전략적 적합성과 실제 실행 가능성을 종합적으로 고려한다. | BD16: 조직의 일부 IT 기능을 외부 전문 업체에 위탁하여 수행하게 하는 것이다. | BE16: 보안 위협이 완전히 제거되어 정보 보안이 강화된다. | BF16: O | BG16: O | BH16: X | BI16: =10*SUMPRODUCT(--(AY16:BH16<>""),--(((AY16:BH16=정답표!$C$10:$L$10)+(AY16:BH16=정답표!$C$11:$L$11))>0)) -> 100 | BJ16: =SUM(Q16,AB16,AM16,AX16,BI16) -> 400 | BK16: =COUNT(Q16,AB16,AM16,AX16,BI16) -> 4 | BL16: =IF(QuizMatchTable[[#This Row],[분반]]=1, QuizMatchTable[[#This Row],[퀴즈합계]]/4 *0.3, QuizMatchTable[[#This Row],[퀴즈합계]]/5*0.3) -> 30 | BM16: 26 | BN16: 20 | BP16: =SUM(QuizMatchTable[[#This Row],[퀴즈점수(30)]],BM16,BN16,BO16) -> 76 | BQ16: =IF(OR(BP16="",BP16=0,BT16="결석초과"),"",COUNTIFS($B$2:$B$109,B16,$BP$2:$BP$109,">"&BP16)+1) -> 2 | BR16: A+ | BS16: 6
A17: 경영학과 | B17: 1 | C17: 20250945 | D17: 최민주 | E17: 010-5005-8659 | F17: cmj5005@naver.com | R17: BPR | S17: 일상적인 운영을 위한 공식적이고 표준화된 절차를 따릅니다. | T17: 기업 간 프로세스 | U17: 동일한 데이터가 여러 부서에 중복 저장되어 불일치가 발생합니다. | V17: 전사적 정보시스템(EIS) 도입 | W17: 불필요한 승인 단계를 축소하여 시간과 자원을 최소화합니다. | X17: 고객과의 모든 상호작용을 통합 관리하여 고객 평생 가치를 극대화하는 것입니다. | Y17: 비즈니스 운영을 단일하고 일관된 컴퓨팅 플랫폼에 통합하는 것입니다. | Z17: O | AA17: O | AB17: =10*SUMPRODUCT(--(R17:AA17<>""),--(((R17:AA17=정답표!$C$4:$L$4)+(R17:AA17=정답표!$C$5:$L$5))>0)) -> 100 | AC17: 하드웨어,소프트웨어,커뮤니티,절차,사람 | AD17: 조직 전략이 가치 사슬을 결정하고, 가치 사슬은 비즈니스 프로세스를, 프로세스는 SMIS 요구 사항을 결정합니다. | AE17: 개인적 강화 | AF17: 사용자 데이터 직접 판매: 사용자의 개인 데이터를 직접 판매하여 주된 수익을 얻습니다. | AG17: 상식 (Common Sense) | AH17: 인공지능(AI)이 생성한 가짜 뉴스나 딥페이크 콘텐츠가 확산되는 소셜 미디어의 어두운 면을 지칭합니다. | AI17: 일방향 통신을 통해 정보가 전달되며, 사용자 간의 상호작용은 제한적입니다. | AJ17: 제조 및 운영 | AK17: O | AL17: O | AM17: =10*SUMPRODUCT(--(AC17:AL17<>""),--(((AC17:AL17=정답표!$C$6:$L$6)+(AC17:AL17=정답표!$C$7:$L$7))>0)) -> 40 | AY17: 조직의 목표 달성을 위해 IT 기술을 지원하고 경영 목표와 연결한다. | AZ17: 정보시스템(IS) 전략과 기업의 경영전략을 효과적으로 연결한다. | BA17: 조직의 목표와 우선순위에 맞춰 전략, 예산, 위험을 함께 고려한다. | BB17: 정보시스템 관련 의사결정을 누가 하고 그에 대한 책임은 누가 지는가? | BC17: 프로젝트의 전략적 적합성과 실제 실행 가능성을 종합적으로 고려한다. | BD17: 조직의 일부 IT 기능을 외부 전문 업체에 위탁하여 수행하게 하는 것이다. | BE17: 보안 위협이 완전히 제거되어 정보 보안이 강화된다. | BF17: O | BG17: O | BH17: X | BI17: =10*SUMPRODUCT(--(AY17:BH17<>""),--(((AY17:BH17=정답표!$C$10:$L$10)+(AY17:BH17=정답표!$C$11:$L$11))>0)) -> 100 | BJ17: =SUM(Q17,AB17,AM17,AX17,BI17) -> 240 | BK17: =COUNT(Q17,AB17,AM17,AX17,BI17) -> 3 | BL17: =IF(QuizMatchTable[[#This Row],[분반]]=1, QuizMatchTable[[#This Row],[퀴즈합계]]/4 *0.3, QuizMatchTable[[#This Row],[퀴즈합계]]/5*0.3) -> 18 | BM17: 26 | BN17: 19.6 | BP17: =SUM(QuizMatchTable[[#This Row],[퀴즈점수(30)]],BM17,BN17,BO17) -> 63.6 | BQ17: =IF(OR(BP17="",BP17=0,BT17="결석초과"),"",COUNTIFS($B$2:$B$109,B17,$BP$2:$BP$109,">"&BP17)+1) -> 12 | BR17: B+ | BS17: 6
A18: 경영학과 | B18: 1 | C18: 20251606 | D18: 강승회 | E18: 010-5519-9991 | F18: jiangchenghui09@gmail.com | G18: B. 피드백 및 반복 (反馈和迭代) | H18: D. 최소한의 비용과 시간 소모 (最低限度的成本和时间消耗) | I18: C. 운영적 의사결정 (运营性决策) | J18: C. 마케팅 전략 (营销策略) | K18: C. 문제해결 (问题解决) | L18: A. 계획 → 착수 → 실행 → 마무리 (计划 → 启动 → 执行 → 结束) | M18: A. 프로젝트 콘텐츠 (项目内容/产出物) | N18: B. 비동기적 소통 (Asynchronous Communication / 异步沟通) | O18: O (참/对) | P18: O (참/对) | Q18: =10*SUMPRODUCT(--(G18:P18<>""),--(((G18:P18=정답표!$C$2:$L$2)+(G18:P18=정답표!$C$3:$L$3))>0)) -> 70 | AY18: 支持IT技术以实现组织目标，并将其与经营目标相结合。 | AZ18: 有效连接信息系统(IS)战略与企业经营战略。 | BA18: 根据组织的目标和优先顺序，综合考虑战略、预算和风险。 | BB18: 谁最擅长操作电脑并拥有技术专业知识？ | BC18: 综合考虑项目的战略适用性和实际可行性。 | BD18: 将组织的部分IT功能委托给外部专业公司执行。 | BE18: 安全威胁完全消除，信息安全得到加强。 | BF18: O | BG18: O | BH18: X | BI18: =10*SUMPRODUCT(--(AY18:BH18<>""),--(((AY18:BH18=정답표!$C$10:$L$10)+(AY18:BH18=정답표!$C$11:$L$11))>0)) -> 90 | BJ18: =SUM(Q18,AB18,AM18,AX18,BI18) -> 160 | BK18: =COUNT(Q18,AB18,AM18,AX18,BI18) -> 2 | BL18: =IF(QuizMatchTable[[#This Row],[분반]]=1, QuizMatchTable[[#This Row],[퀴즈합계]]/4 *0.3, QuizMatchTable[[#This Row],[퀴즈합계]]/5*0.3) -> 12 | BM18: 22 | BN18: 0 | BP18: =SUM(QuizMatchTable[[#This Row],[퀴즈점수(30)]],BM18,BN18,BO18) -> 34 | BQ18: =IF(OR(BP18="",BP18=0,BT18="결석초과"),"",COUNTIFS($B$2:$B$109,B18,$BP$2:$BP$109,">"&BP18)+1) -> 21 | BR18: F | BS18: 12
A19: 경영학과 | B19: 1 | C19: 20251670 | D19: 김준우 | E19: 010-5541-3529 | F19: jogaehana@gmail.com | G19: B. 피드백 및 반복 (反馈和迭代) | H19: D. 최소한의 비용과 시간 소모 (最低限度的成本和时间消耗) | I19: C. 운영적 의사결정 (运营性决策) | J19: C. 마케팅 전략 (营销策略) | K19: C. 문제해결 (问题解决) | L19: C. 착수 → 계획 → 실행 → 마무리 (启动 → 计划 → 执行 → 结束) | M19: A. 프로젝트 콘텐츠 (项目内容/产出物), B. 프로젝트 메타데이터 (项目元数据) | N19: B. 비동기적 소통 (Asynchronous Communication / 异步沟通) | O19: X (거짓/错) | P19: O (참/对) | Q19: =10*SUMPRODUCT(--(G19:P19<>""),--(((G19:P19=정답표!$C$2:$L$2)+(G19:P19=정답표!$C$3:$L$3))>0)) -> 100 | R19: BPR | S19: 일상적인 운영을 위한 공식적이고 표준화된 절차를 따릅니다. | T19: 기업 간 프로세스 | U19: 동일한 데이터가 여러 부서에 중복 저장되어 불일치가 발생합니다. | V19: 전사적 정보시스템(EIS) 도입 | W19: 불필요한 승인 단계를 축소하여 시간과 자원을 최소화합니다. | X19: 고객과의 모든 상호작용을 통합 관리하여 고객 평생 가치를 극대화하는 것입니다. | Y19: 비즈니스 운영을 단일하고 일관된 컴퓨팅 플랫폼에 통합하는 것입니다. | Z19: O | AA19: O | AB19: =10*SUMPRODUCT(--(R19:AA19<>""),--(((R19:AA19=정답표!$C$4:$L$4)+(R19:AA19=정답표!$C$5:$L$5))>0)) -> 100 | AY19: 조직의 목표 달성을 위해 IT 기술을 지원하고 경영 목표와 연결한다. | AZ19: 정보시스템(IS) 전략과 기업의 경영전략을 효과적으로 연결한다. | BA19: 조직의 목표와 우선순위에 맞춰 전략, 예산, 위험을 함께 고려한다. | BB19: 정보시스템 관련 의사결정을 누가 하고 그에 대한 책임은 누가 지는가? | BC19: 프로젝트의 전략적 적합성과 실제 실행 가능성을 종합적으로 고려한다. | BD19: 조직의 일부 IT 기능을 외부 전문 업체에 위탁하여 수행하게 하는 것이다. | BE19: 보안 위협이 완전히 제거되어 정보 보안이 강화된다. | BF19: O | BG19: O | BH19: X | BI19: =10*SUMPRODUCT(--(AY19:BH19<>""),--(((AY19:BH19=정답표!$C$10:$L$10)+(AY19:BH19=정답표!$C$11:$L$11))>0)) -> 100 | BJ19: =SUM(Q19,AB19,AM19,AX19,BI19) -> 300 | BK19: =COUNT(Q19,AB19,AM19,AX19,BI19) -> 3 | BL19: =IF(QuizMatchTable[[#This Row],[분반]]=1, QuizMatchTable[[#This Row],[퀴즈합계]]/4 *0.3, QuizMatchTable[[#This Row],[퀴즈합계]]/5*0.3) -> 22.5 | BM19: 26 | BN19: 20 | BP19: =SUM(QuizMatchTable[[#This Row],[퀴즈점수(30)]],BM19,BN19,BO19) -> 68.5 | BQ19: =IF(OR(BP19="",BP19=0,BT19="결석초과"),"",COUNTIFS($B$2:$B$109,B19,$BP$2:$BP$109,">"&BP19)+1) -> 7 | BR19: A0 | BS19: 6
A20: 경영학과 | B20: 1 | C20: 20251672 | D20: 박건우 | E20: 010-4398-8123 | F20: gunukingg05@gmail.com | BL20: =IF(QuizMatchTable[[#This Row],[분반]]=1, QuizMatchTable[[#This Row],[퀴즈합계]]/4 *0.3, QuizMatchTable[[#This Row],[퀴즈합계]]/5*0.3) -> 0 | BM20: 0 | BN20: 0 | BP20: =SUM(QuizMatchTable[[#This Row],[퀴즈점수(30)]],BM20,BN20,BO20) -> 0 | BQ20: =IF(OR(BP20="",BP20=0,BT20="결석초과"),"",COUNTIFS($B$2:$B$109,B20,$BP$2:$BP$109,">"&BP20)+1) | BR20: F | BS20: 33 | BT20: 결석초과
A21: 경영학과 | B21: 1 | C21: 20251909 | D21: 고하우 | E21: 010-8267-4006 | F21: 516970470@qq.com | AY21: 支持IT技术以实现组织目标，并将其与经营目标相结合。 | AZ21: 有效连接信息系统(IS)战略与企业经营战略。 | BA21: 根据组织的目标和优先顺序，综合考虑战略、预算和风险。 | BB21: 谁来做信息系统相关的决策，谁来承担责任？ | BC21: 综合考虑项目的战略适用性和实际可行性。 | BD21: 将组织的部分IT功能委托给外部专业公司执行。 | BE21: 安全威胁完全消除，信息安全得到加强。 | BF21: O | BG21: O | BH21: X | BI21: =10*SUMPRODUCT(--(AY21:BH21<>""),--(((AY21:BH21=정답표!$C$10:$L$10)+(AY21:BH21=정답표!$C$11:$L$11))>0)) -> 100 | BJ21: =SUM(Q21,AB21,AM21,AX21,BI21) -> 100 | BK21: =COUNT(Q21,AB21,AM21,AX21,BI21) -> 1 | BL21: =IF(QuizMatchTable[[#This Row],[분반]]=1, QuizMatchTable[[#This Row],[퀴즈합계]]/4 *0.3, QuizMatchTable[[#This Row],[퀴즈합계]]/5*0.3) -> 7.5 | BM21: 0 | BN21: 0 | BP21: =SUM(QuizMatchTable[[#This Row],[퀴즈점수(30)]],BM21,BN21,BO21) -> 7.5 | BQ21: =IF(OR(BP21="",BP21=0,BT21="결석초과"),"",COUNTIFS($B$2:$B$109,B21,$BP$2:$BP$109,">"&BP21)+1) | BR21: F | BS21: 18 | BT21: 결석초과
A22: 경영학과 | B22: 1 | C22: 20251910 | D22: 서만 | E22: 010-7631-6213 | F22: x31_0113@qq.com | R22: BPR | S22: 遵循日常运营的正式化和标准化程序。 | T22: 企业间流程 | U22: 相同数据在多个部门重复存储，导致不一致。 | V22: 引入企业信息系统（EIS） | W22: 减少不必要的审批环节，从而最大限度地减少时间和资源。 | X22: 整合管理与客户的所有互动，最大限度地提高客户终身价值。 | Y22: 将业务运营整合到一个单一且一致的计算平台。 | Z22: O | AA22: O | AB22: =10*SUMPRODUCT(--(R22:AA22<>""),--(((R22:AA22=정답표!$C$4:$L$4)+(R22:AA22=정답표!$C$5:$L$5))>0)) -> 100 | AC22: 硬件、软件、数据、流程、人员 | AD22: 组织战略决定价值链，价值链决定业务流程，业务流程决定 SMIS 需求。 | AE22: 增加物质资本 | AF22: 直接销售用户数据：通过直接销售用户个人数据获取主要收入。 | AG22: 常识 (Common Sense) | AH22: 指通过电子邮件、消息应用等难以追踪的渠道进行的社交分享区域，企业应在此处关注建立信任。 | AI22: 基于兴趣形成，一个用户可以同时属于多个社区。 | AJ22: 财务与会计 | AK22: O | AL22: O | AM22: =10*SUMPRODUCT(--(AC22:AL22<>""),--(((AC22:AL22=정답표!$C$6:$L$6)+(AC22:AL22=정답표!$C$7:$L$7))>0)) -> 90 | AY22: 支持IT技术以实现组织目标，并将其与经营目标相结合。 | AZ22: 有效连接信息系统(IS)战略与企业经营战略。 | BA22: 根据组织的目标和优先顺序，综合考虑战略、预算和风险。 | BB22: 谁来做信息系统相关的决策，谁来承担责任？ | BC22: 综合考虑项目的战略适用性和实际可行性。 | BD22: 将组织的部分IT功能委托给外部专业公司执行。 | BE22: 安全威胁完全消除，信息安全得到加强。 | BF22: O | BG22: O | BH22: X | BI22: =10*SUMPRODUCT(--(AY22:BH22<>""),--(((AY22:BH22=정답표!$C$10:$L$10)+(AY22:BH22=정답표!$C$11:$L$11))>0)) -> 100 | BJ22: =SUM(Q22,AB22,AM22,AX22,BI22) -> 290 | BK22: =COUNT(Q22,AB22,AM22,AX22,BI22) -> 3 | BL22: =IF(QuizMatchTable[[#This Row],[분반]]=1, QuizMatchTable[[#This Row],[퀴즈합계]]/4 *0.3, QuizMatchTable[[#This Row],[퀴즈합계]]/5*0.3) -> 21.75 | BM22: 28 | BN22: 16.8 | BP22: =SUM(QuizMatchTable[[#This Row],[퀴즈점수(30)]],BM22,BN22,BO22) -> 66.55 | BQ22: =IF(OR(BP22="",BP22=0,BT22="결석초과"),"",COUNTIFS($B$2:$B$109,B22,$BP$2:$BP$109,">"&BP22)+1) -> 10 | BR22: B+ | BS22: 3
A23: 경영학과 | B23: 1 | C23: 20251913 | D23: 장호연 | E23: 010-8247-5841 | F23: 516970470@qq.com | R23: BPR | S23: 遵循日常运营的正式化和标准化程序。 | T23: 企业间流程 | U23: 相同数据在多个部门重复存储，导致不一致。 | V23: 引入企业信息系统（EIS） | W23: 减少不必要的审批环节，从而最大限度地减少时间和资源。 | X23: 整合管理与客户的所有互动，最大限度地提高客户终身价值。 | Y23: 将业务运营整合到一个单一且一致的计算平台。 | Z23: O | AA23: O | AB23: =10*SUMPRODUCT(--(R23:AA23<>""),--(((R23:AA23=정답표!$C$4:$L$4)+(R23:AA23=정답표!$C$5:$L$5))>0)) -> 100 | BJ23: =SUM(Q23,AB23,AM23,AX23,BI23) -> 100 | BK23: =COUNT(Q23,AB23,AM23,AX23,BI23) -> 1 | BL23: =IF(QuizMatchTable[[#This Row],[분반]]=1, QuizMatchTable[[#This Row],[퀴즈합계]]/4 *0.3, QuizMatchTable[[#This Row],[퀴즈합계]]/5*0.3) -> 7.5 | BM23: 0 | BN23: 0 | BP23: =SUM(QuizMatchTable[[#This Row],[퀴즈점수(30)]],BM23,BN23,BO23) -> 7.5 | BQ23: =IF(OR(BP23="",BP23=0,BT23="결석초과"),"",COUNTIFS($B$2:$B$109,B23,$BP$2:$BP$109,">"&BP23)+1) | BR23: F | BS23: 24 | BT23: 결석초과
A24: 경영학과 | B24: 1 | C24: 20251915 | D24: 호티안뚜엔 | E24: 010-5592-6663 | F24: anhtuyen0425@gmail.com | G24: B. 피드백 및 반복 (反馈和迭代) | H24: D. 최소한의 비용과 시간 소모 (最低限度的成本和时间消耗) | I24: C. 운영적 의사결정 (运营性决策) | J24: C. 마케팅 전략 (营销策略) | K24: C. 문제해결 (问题解决) | L24: C. 착수 → 계획 → 실행 → 마무리 (启动 → 计划 → 执行 → 结束) | M24: A. 프로젝트 콘텐츠 (项目内容/产出物) | N24: B. 비동기적 소통 (Asynchronous Communication / 异步沟通) | O24: X (거짓/错) | P24: O (참/对) | Q24: =10*SUMPRODUCT(--(G24:P24<>""),--(((G24:P24=정답표!$C$2:$L$2)+(G24:P24=정답표!$C$3:$L$3))>0)) -> 90 | R24: BPR | S24: 일상적인 운영을 위한 공식적이고 표준화된 절차를 따릅니다. | T24: 기업 간 프로세스 | U24: 동일한 데이터가 여러 부서에 중복 저장되어 불일치가 발생합니다. | V24: 전사적 정보시스템(EIS) 도입 | W24: 불필요한 승인 단계를 축소하여 시간과 자원을 최소화합니다. | X24: 고객과의 모든 상호작용을 통합 관리하여 고객 평생 가치를 극대화하는 것입니다. | Y24: 비즈니스 운영을 단일하고 일관된 컴퓨팅 플랫폼에 통합하는 것입니다. | Z24: O | AA24: O | AB24: =10*SUMPRODUCT(--(R24:AA24<>""),--(((R24:AA24=정답표!$C$4:$L$4)+(R24:AA24=정답표!$C$5:$L$5))>0)) -> 100 | AC24: 콘텐츠, 플랫폼, 네트워크,가치사슬,하드웨어 | AD24: 조직 전략이 가치 사슬을 결정하고, 가치 사슬은 비즈니스 프로세스를, 프로세스는 SMIS 요구 사항을 결정합니다. | AE24: 정보 획득 | AF24: 제휴 및 소셜 커머스: 추천 링크를 통한 판매 수수료나 실시간 쇼핑을 통해 수익을 창출합니다. | AG24: 투명성 (Disclosure) | AH24: 인공지능(AI)이 생성한 가짜 뉴스나 딥페이크 콘텐츠가 확산되는 소셜 미디어의 어두운 면을 지칭합니다. | AI24: 주로 지리적 근접성을 기반으로 형성되어 구성원 간의 유대감이 강합니다. | AJ24: 판매 및 마케팅 | AK24: X | AL24: O | AM24: =10*SUMPRODUCT(--(AC24:AL24<>""),--(((AC24:AL24=정답표!$C$6:$L$6)+(AC24:AL24=정답표!$C$7:$L$7))>0)) -> 20 | BJ24: =SUM(Q24,AB24,AM24,AX24,BI24) -> 210 | BK24: =COUNT(Q24,AB24,AM24,AX24,BI24) -> 3 | BL24: =IF(QuizMatchTable[[#This Row],[분반]]=1, QuizMatchTable[[#This Row],[퀴즈합계]]/4 *0.3, QuizMatchTable[[#This Row],[퀴즈합계]]/5*0.3) -> 15.75 | BM24: 26 | BN24: 14.8 | BP24: =SUM(QuizMatchTable[[#This Row],[퀴즈점수(30)]],BM24,BN24,BO24) -> 56.55 | BQ24: =IF(OR(BP24="",BP24=0,BT24="결석초과"),"",COUNTIFS($B$2:$B$109,B24,$BP$2:$BP$109,">"&BP24)+1) -> 16 | BR24: B0 | BS24: 6
A25: 경영학과 | B25: 1 | C25: 23310011 | D25: 김호영 | E25: 010-2041-8336 | F25: khy040722@naver.com | AC25: 하드웨어,소프트웨어,커뮤니티,절차,사람 | AD25: 조직 전략이 가치 사슬을 결정하고, 가치 사슬은 비즈니스 프로세스를, 프로세스는 SMIS 요구 사항을 결정합니다. | AE25: 물적 자본 증대 | AF25: 사용자 데이터 직접 판매: 사용자의 개인 데이터를 직접 판매하여 주된 수익을 얻습니다. | AG25: 혁신 (Innovation) | AH25: 이메일, 메시징 앱 등 추적하기 어려운 채널을 통한 소셜 공유 영역을 의미하며, 비즈니스는 여기서 신뢰 구축에 주목해야 합니다. | AI25: 관심사 기반으로 형성되며, 한 명의 사용자가 여러 커뮤니티에 동시 소속될 수 있습니다. | AJ25: 재무 및 회계 | AK25: O | AL25: O | AM25: =10*SUMPRODUCT(--(AC25:AL25<>""),--(((AC25:AL25=정답표!$C$6:$L$6)+(AC25:AL25=정답표!$C$7:$L$7))>0)) -> 90 | AY25: 조직의 목표 달성을 위해 IT 기술을 지원하고 경영 목표와 연결한다. | AZ25: 정보시스템(IS) 전략과 기업의 경영전략을 효과적으로 연결한다. | BA25: 조직의 목표와 우선순위에 맞춰 전략, 예산, 위험을 함께 고려한다. | BB25: 정보시스템 관련 의사결정을 누가 하고 그에 대한 책임은 누가 지는가? | BC25: 프로젝트의 전략적 적합성과 실제 실행 가능성을 종합적으로 고려한다. | BD25: 조직의 일부 IT 기능을 외부 전문 업체에 위탁하여 수행하게 하는 것이다. | BE25: 보안 위협이 완전히 제거되어 정보 보안이 강화된다. | BF25: O | BG25: O | BH25: X | BI25: =10*SUMPRODUCT(--(AY25:BH25<>""),--(((AY25:BH25=정답표!$C$10:$L$10)+(AY25:BH25=정답표!$C$11:$L$11))>0)) -> 100 | BJ25: =SUM(Q25,AB25,AM25,AX25,BI25) -> 190 | BK25: =COUNT(Q25,AB25,AM25,AX25,BI25) -> 2 | BL25: =IF(QuizMatchTable[[#This Row],[분반]]=1, QuizMatchTable[[#This Row],[퀴즈합계]]/4 *0.3, QuizMatchTable[[#This Row],[퀴즈합계]]/5*0.3) -> 14.25 | BM25: 26 | BN25: 20 | BP25: =SUM(QuizMatchTable[[#This Row],[퀴즈점수(30)]],BM25,BN25,BO25) -> 60.25 | BQ25: =IF(OR(BP25="",BP25=0,BT25="결석초과"),"",COUNTIFS($B$2:$B$109,B25,$BP$2:$BP$109,">"&BP25)+1) -> 13 | BR25: B+ | BS25: 6
A26: 경영학과 | B26: 1 | C26: 24510006 | D26: 송유안 | E26: 010-4995-0377 | F26: sshj8955@naver.com | G26: B. 피드백 및 반복 (反馈和迭代) | H26: D. 최소한의 비용과 시간 소모 (最低限度的成本和时间消耗) | I26: C. 운영적 의사결정 (运营性决策) | J26: C. 마케팅 전략 (营销策略) | K26: C. 문제해결 (问题解决) | L26: C. 착수 → 계획 → 실행 → 마무리 (启动 → 计划 → 执行 → 结束) | M26: A. 프로젝트 콘텐츠 (项目内容/产出物) | N26: B. 비동기적 소통 (Asynchronous Communication / 异步沟通) | O26: X (거짓/错) | P26: O (참/对) | Q26: =10*SUMPRODUCT(--(G26:P26<>""),--(((G26:P26=정답표!$C$2:$L$2)+(G26:P26=정답표!$C$3:$L$3))>0)) -> 90 | R26: BPR | S26: 조직의 변화에 따라 프로세스 구조가 신속하게 적응하고 변경됩니다. | T26: 기업 간 프로세스 | U26: 동일한 데이터가 여러 부서에 중복 저장되어 불일치가 발생합니다. | V26: 전사적 정보시스템(EIS) 도입 | W26: 불필요한 승인 단계를 축소하여 시간과 자원을 최소화합니다. | X26: 고객과의 모든 상호작용을 통합 관리하여 고객 평생 가치를 극대화하는 것입니다. | Y26: 기존에 분리된 시스템들 간의 데이터 공유 및 통신을 가능하게 하는 것입니다. | Z26: X | AA26: O | AB26: =10*SUMPRODUCT(--(R26:AA26<>""),--(((R26:AA26=정답표!$C$4:$L$4)+(R26:AA26=정답표!$C$5:$L$5))>0)) -> 70 | BJ26: =SUM(Q26,AB26,AM26,AX26,BI26) -> 160 | BK26: =COUNT(Q26,AB26,AM26,AX26,BI26) -> 2 | BL26: =IF(QuizMatchTable[[#This Row],[분반]]=1, QuizMatchTable[[#This Row],[퀴즈합계]]/4 *0.3, QuizMatchTable[[#This Row],[퀴즈합계]]/5*0.3) -> 12 | BM26: 0 | BN26: 20 | BP26: =SUM(QuizMatchTable[[#This Row],[퀴즈점수(30)]],BM26,BN26,BO26) -> 32 | BQ26: =IF(OR(BP26="",BP26=0,BT26="결석초과"),"",COUNTIFS($B$2:$B$109,B26,$BP$2:$BP$109,">"&BP26)+1) | BR26: F | BS26: 18 | BT26: 결석초과
A27: 경영학과 | B27: 1 | C27: 24510097 | D27: 이지영 | E27: 010-8839-8874 | F27: 2jy1018@gmail.com | G27: B. 피드백 및 반복 (反馈和迭代) | H27: D. 최소한의 비용과 시간 소모 (最低限度的成本和时间消耗) | I27: C. 운영적 의사결정 (运营性决策) | J27: C. 마케팅 전략 (营销策略) | K27: C. 문제해결 (问题解决) | L27: C. 착수 → 계획 → 실행 → 마무리 (启动 → 计划 → 执行 → 结束) | M27: A. 프로젝트 콘텐츠 (项目内容/产出物), B. 프로젝트 메타데이터 (项目元数据) | N27: B. 비동기적 소통 (Asynchronous Communication / 异步沟通) | O27: X (거짓/错) | P27: O (참/对) | Q27: =10*SUMPRODUCT(--(G27:P27<>""),--(((G27:P27=정답표!$C$2:$L$2)+(G27:P27=정답표!$C$3:$L$3))>0)) -> 100 | AC27: 하드웨어,소프트웨어,데이터,절차,사람 | AD27: 조직 전략이 가치 사슬을 결정하고, 가치 사슬은 비즈니스 프로세스를, 프로세스는 SMIS 요구 사항을 결정합니다. | AE27: 물적 자본 증대 | AF27: 사용자 데이터 직접 판매: 사용자의 개인 데이터를 직접 판매하여 주된 수익을 얻습니다. | AG27: 혁신 (Innovation) | AH27: 이메일, 메시징 앱 등 추적하기 어려운 채널을 통한 소셜 공유 영역을 의미하며, 비즈니스는 여기서 신뢰 구축에 주목해야 합니다. | AI27: 관심사 기반으로 형성되며, 한 명의 사용자가 여러 커뮤니티에 동시 소속될 수 있습니다. | AJ27: 재무 및 회계 | AK27: O | AL27: O | AM27: =10*SUMPRODUCT(--(AC27:AL27<>""),--(((AC27:AL27=정답표!$C$6:$L$6)+(AC27:AL27=정답표!$C$7:$L$7))>0)) -> 100 | AY27: 조직의 목표 달성을 위해 IT 기술을 지원하고 경영 목표와 연결한다. | AZ27: 정보시스템(IS) 전략과 기업의 경영전략을 효과적으로 연결한다. | BA27: 조직의 목표와 우선순위에 맞춰 전략, 예산, 위험을 함께 고려한다. | BB27: 정보시스템 관련 의사결정을 누가 하고 그에 대한 책임은 누가 지는가? | BC27: 프로젝트의 전략적 적합성과 실제 실행 가능성을 종합적으로 고려한다. | BD27: 조직의 일부 IT 기능을 외부 전문 업체에 위탁하여 수행하게 하는 것이다. | BE27: 보안 위협이 완전히 제거되어 정보 보안이 강화된다. | BF27: O | BG27: O | BH27: X | BI27: =10*SUMPRODUCT(--(AY27:BH27<>""),--(((AY27:BH27=정답표!$C$10:$L$10)+(AY27:BH27=정답표!$C$11:$L$11))>0)) -> 100 | BJ27: =SUM(Q27,AB27,AM27,AX27,BI27) -> 300 | BK27: =COUNT(Q27,AB27,AM27,AX27,BI27) -> 3 | BL27: =IF(QuizMatchTable[[#This Row],[분반]]=1, QuizMatchTable[[#This Row],[퀴즈합계]]/4 *0.3, QuizMatchTable[[#This Row],[퀴즈합계]]/5*0.3) -> 22.5 | BM27: 22 | BN27: 20 | BP27: =SUM(QuizMatchTable[[#This Row],[퀴즈점수(30)]],BM27,BN27,BO27) -> 64.5 | BQ27: =IF(OR(BP27="",BP27=0,BT27="결석초과"),"",COUNTIFS($B$2:$B$109,B27,$BP$2:$BP$109,">"&BP27)+1) -> 11 | BR27: B+ | BS27: 12
A28: 경영학과 | B28: 2 | C28: 20220130 | D28: 가경란 | E28: 010-7617-6878 | F28: 2068609058@qq.com | G28: B. 피드백 및 반복 (反馈和迭代) | H28: D. 최소한의 비용과 시간 소모 (最低限度的成本和时间消耗) | I28: C. 운영적 의사결정 (运营性决策) | J28: C. 마케팅 전략 (营销策略) | K28: C. 문제해결 (问题解决) | L28: C. 착수 → 계획 → 실행 → 마무리 (启动 → 计划 → 执行 → 结束) | M28: A. 프로젝트 콘텐츠 (项目内容/产出物) | N28: B. 비동기적 소통 (Asynchronous Communication / 异步沟通) | O28: X (거짓/错) | P28: O (참/对) | Q28: 90 | R28: BPR | S28: 遵循日常运营的正式化和标准化程序。 | T28: 企业间流程 | U28: 相同数据在多个部门重复存储，导致不一致。 | V28: 引入企业信息系统（EIS） | W28: 减少不必要的审批环节，从而最大限度地减少时间和资源。 | X28: 整合管理与客户的所有互动，最大限度地提高客户终身价值。 | Y28: 将业务运营整合到一个单一且一致的计算平台。 | Z28: O | AA28: O | AB28: 100 | AC28: 硬件、软件、社区、流程、人员 | AD28: 组织战略决定价值链，价值链决定业务流程，业务流程决定 SMIS 需求。 | AE28: 增加物质资本 | AF28: 直接销售用户数据：通过直接销售用户个人数据获取主要收入。 | AG28: 创新 (Innovation) | AH28: 指通过电子邮件、消息应用等难以追踪的渠道进行的社交分享区域，企业应在此处关注建立信任。 | AI28: 基于兴趣形成，一个用户可以同时属于多个社区。 | AJ28: 财务与会计 | AK28: O | AL28: O | AM28: 90 | AN28: 在风险、成本和便利性之间找到适当的平衡。 | AO28: 因为将所有安全风险降至零在现实中是不可能且低效的。 | AP28: 未应用安全补丁的旧软件 | AQ28: 威胁能够访问系统或数据并造成损害的弱点。 | AR28: 将数据转换为未经授权的人无法理解的形式以进行保护的技术。 | AS28: 根据预设规则允许或阻止网络流量。 | AT28: 主要是技术部门制定和执行的技术问题。 | AU28: 定期测试备份数据是否能实际恢复非常重要。 | AV28: O | AW28: O | AX28: 100 | AY28: 支持IT技术以实现组织目标，并将其与经营目标相结合。 | AZ28: 有效连接信息系统(IS)战略与企业经营战略。 | BA28: 根据组织的目标和优先顺序，综合考虑战略、预算和风险。 | BB28: 谁来做信息系统相关的决策，谁来承担责任？ | BC28: 综合考虑项目的战略适用性和实际可行性。 | BD28: 将组织的部分IT功能委托给外部专业公司执行。 | BE28: 安全威胁完全消除，信息安全得到加强。 | BF28: O | BG28: O | BH28: X | BI28: 100 | BJ28: 480 | BK28: 5 | BL28: =IF(QuizMatchTable[[#This Row],[분반]]=1, QuizMatchTable[[#This Row],[퀴즈합계]]/4 *0.3, QuizMatchTable[[#This Row],[퀴즈합계]]/5*0.3) -> 28.8 | BM28: 30 | BN28: 18.8 | BP28: =SUM(QuizMatchTable[[#This Row],[퀴즈점수(30)]],BM28,BN28,BO28) -> 77.6 | BQ28: =IF(OR(BP28="",BP28=0,BT28="결석초과"),"",COUNTIFS($B$2:$B$109,B28,$BP$2:$BP$109,">"&BP28)+1) -> 9 | BR28: B+ | BS28: 0
A29: 경영학과 | B29: 2 | C29: 20220131 | D29: 강합문호 | E29: 010-2249-1040 | F29: 2024117631@qq.com | G29: B. 피드백 및 반복 (反馈和迭代) | H29: D. 최소한의 비용과 시간 소모 (最低限度的成本和时间消耗) | I29: D. 비구조적 의사결정 (非结构性决策) | J29: C. 마케팅 전략 (营销策略) | K29: B. 의사결정 (决策制定) | L29: C. 착수 → 계획 → 실행 → 마무리 (启动 → 计划 → 执行 → 结束) | M29: B. 프로젝트 메타데이터 (项目元数据) | N29: B. 비동기적 소통 (Asynchronous Communication / 异步沟通) | O29: O (참/对) | P29: O (참/对) | Q29: =10*SUMPRODUCT(--(G29:P29<>""),--(((G29:P29=정답표!$C$2:$L$2)+(G29:P29=정답표!$C$3:$L$3))>0)) -> 60 | R29: CRM | S29: 频繁发生例外情况，并被设计为能够适应这些情况。 | T29: 工作组流程 | U29: 相同数据在多个部门重复存储，导致不一致。 | V29: 加强安全以防止数据泄露 | W29: 减少不必要的审批环节，从而最大限度地减少时间和资源。 | X29: 在单一平台上自动化企业的财务、会计和制造流程。 | Y29: 实现现有分离系统之间的数据共享和通信。 | Z29: O | AA29: X | AB29: =10*SUMPRODUCT(--(R29:AA29<>""),--(((R29:AA29=정답표!$C$4:$L$4)+(R29:AA29=정답표!$C$5:$L$5))>0)) -> 30 | AC29: 内容、平台、网络、价值链、硬件 | AD29: 业务流程决定 SMIS 需求，然后反过来塑造组织战略和价值链。 | AE29: 个人赋能 | AF29: 直接销售用户数据：通过直接销售用户个人数据获取主要收入。 | AG29: 创新 (Innovation) | AH29: 指人工智能 (AI) 生成的假新闻或深度伪造内容在社交媒体上传播的阴暗面。 | AI29: 基于兴趣形成，一个用户可以同时属于多个社区。 | AJ29: 销售与营销 | AK29: X | AL29: X | AM29: =10*SUMPRODUCT(--(AC29:AL29<>""),--(((AC29:AL29=정답표!$C$6:$L$6)+(AC29:AL29=정답표!$C$7:$L$7))>0)) -> 30 | AN29: 在风险、成本和便利性之间找到适当的平衡。 | AO29: 因为信息系统的复杂性增加，导致安全管理的难度提高。 | AP29: 存储重要客户信息的数据库 | AQ29: 外部试图绕过安全系统进行非法访问的行为。 | AR29: 将数据转换为未经授权的人无法理解的形式以进行保护的技术。 | AS29: 根据预设规则允许或阻止网络流量。 | AT29: 主要是技术部门制定和执行的技术问题。 | AU29: 定期测试备份数据是否能实际恢复非常重要。 | AV29: O | AW29: X | AX29: =10*SUMPRODUCT(--(AN29:AW29<>""),--(((AN29:AW29=정답표!$C$8:$L$8)+(AN29:AW29=정답표!$C$9:$L$9))>0)) -> 60 | AY29: 直接执行和管理组织内的所有业务流程。 | AZ29: 有效连接信息系统(IS)战略与企业经营战略。 | BA29: 根据组织的目标和优先顺序，综合考虑战略、预算和风险。 | BB29: 哪个部门使用的信息系统相关预算最多？ | BC29: 综合考虑项目的战略适用性和实际可行性。 | BD29: 将组织的部分IT功能委托给外部专业公司执行。 | BE29: 安全威胁完全消除，信息安全得到加强。 | BF29: X | BG29: X | BH29: X | BI29: =10*SUMPRODUCT(--(AY29:BH29<>""),--(((AY29:BH29=정답표!$C$10:$L$10)+(AY29:BH29=정답표!$C$11:$L$11))>0)) -> 60 | BJ29: =SUM(Q29,AB29,AM29,AX29,BI29) -> 240 | BK29: =COUNT(Q29,AB29,AM29,AX29,BI29) -> 5 | BL29: =IF(QuizMatchTable[[#This Row],[분반]]=1, QuizMatchTable[[#This Row],[퀴즈합계]]/4 *0.3, QuizMatchTable[[#This Row],[퀴즈합계]]/5*0.3) -> 14.4 | BM29: 30 | BN29: 9.6 | BP29: =SUM(QuizMatchTable[[#This Row],[퀴즈점수(30)]],BM29,BN29,BO29) -> 54 | BQ29: =IF(OR(BP29="",BP29=0,BT29="결석초과"),"",COUNTIFS($B$2:$B$109,B29,$BP$2:$BP$109,">"&BP29)+1) -> 32 | BR29: F | BS29: 0
A30: 경영학과 | B30: 2 | C30: 20220132 | D30: 고천양 | E30: 010-8232-2903 | F30: 3340777498@qq.com | G30: C. 분업 및 전문화 (分工和专业化) | H30: D. 최소한의 비용과 시간 소모 (最低限度的成本和时间消耗) | I30: C. 운영적 의사결정 (运营性决策) | J30: C. 마케팅 전략 (营销策略) | K30: C. 문제해결 (问题解决) | L30: C. 착수 → 계획 → 실행 → 마무리 (启动 → 计划 → 执行 → 结束) | M30: B. 프로젝트 메타데이터 (项目元数据) | N30: B. 비동기적 소통 (Asynchronous Communication / 异步沟通) | O30: X (거짓/错) | P30: O (참/对) | Q30: =10*SUMPRODUCT(--(G30:P30<>""),--(((G30:P30=정답표!$C$2:$L$2)+(G30:P30=정답표!$C$3:$L$3))>0)) -> 80 | R30: BPR | S30: 遵循日常运营的正式化和标准化程序。 | T30: 企业级流程 | U30: 相同数据在多个部门重复存储，导致不一致。 | V30: 引入企业信息系统（EIS） | W30: 减少不必要的审批环节，从而最大限度地减少时间和资源。 | X30: 整合管理与客户的所有互动，最大限度地提高客户终身价值。 | Y30: 将业务运营整合到一个单一且一致的计算平台。 | Z30: O | AA30: O | AB30: =10*SUMPRODUCT(--(R30:AA30<>""),--(((R30:AA30=정답표!$C$4:$L$4)+(R30:AA30=정답표!$C$5:$L$5))>0)) -> 90 | AC30: 硬件、软件、数据、流程、人员 | AD30: 组织战略决定价值链，价值链决定业务流程，业务流程决定 SMIS 需求。 | AE30: 增加物质资本 | AF30: 直接销售用户数据：通过直接销售用户个人数据获取主要收入。 | AG30: 创新 (Innovation) | AH30: 指通过电子邮件、消息应用等难以追踪的渠道进行的社交分享区域，企业应在此处关注建立信任。 | AI30: 基于兴趣形成，一个用户可以同时属于多个社区。 | AJ30: 制造与运营 | AK30: O | AL30: O | AM30: =10*SUMPRODUCT(--(AC30:AL30<>""),--(((AC30:AL30=정답표!$C$6:$L$6)+(AC30:AL30=정답표!$C$7:$L$7))>0)) -> 90 | AN30: 在风险、成本和便利性之间找到适当的平衡。 | AO30: 因为将所有安全风险降至零在现实中是不可能且低效的。 | AP30: 未应用安全补丁的旧软件 | AQ30: 威胁能够访问系统或数据并造成损害的弱点。 | AR30: 将数据转换为未经授权的人无法理解的形式以进行保护的技术。 | AS30: 根据预设规则允许或阻止网络流量。 | AT30: 主要是技术部门制定和执行的技术问题。 | AU30: 定期测试备份数据是否能实际恢复非常重要。 | AV30: O | AW30: O | AX30: =10*SUMPRODUCT(--(AN30:AW30<>""),--(((AN30:AW30=정답표!$C$8:$L$8)+(AN30:AW30=정답표!$C$9:$L$9))>0)) -> 100 | AY30: 支持IT技术以实现组织目标，并将其与经营目标相结合。 | AZ30: 有效连接信息系统(IS)战略与企业经营战略。 | BA30: 根据组织的目标和优先顺序，综合考虑战略、预算和风险。 | BB30: 谁来做信息系统相关的决策，谁来承担责任？ | BC30: 综合考虑项目的战略适用性和实际可行性。 | BD30: 将组织的部分IT功能委托给外部专业公司执行。 | BE30: 安全威胁完全消除，信息安全得到加强。 | BF30: O | BG30: O | BH30: X | BI30: =10*SUMPRODUCT(--(AY30:BH30<>""),--(((AY30:BH30=정답표!$C$10:$L$10)+(AY30:BH30=정답표!$C$11:$L$11))>0)) -> 100 | BJ30: =SUM(Q30,AB30,AM30,AX30,BI30) -> 460 | BK30: =COUNT(Q30,AB30,AM30,AX30,BI30) -> 5 | BL30: =IF(QuizMatchTable[[#This Row],[분반]]=1, QuizMatchTable[[#This Row],[퀴즈합계]]/4 *0.3, QuizMatchTable[[#This Row],[퀴즈합계]]/5*0.3) -> 27.6 | BM30: 26 | BN30: 12.8 | BP30: =SUM(QuizMatchTable[[#This Row],[퀴즈점수(30)]],BM30,BN30,BO30) -> 66.4 | BQ30: =IF(OR(BP30="",BP30=0,BT30="결석초과"),"",COUNTIFS($B$2:$B$109,B30,$BP$2:$BP$109,">"&BP30)+1) -> 28 | BR30: F | BS30: 6
A31: 경영학과 | B31: 2 | C31: 20220133 | D31: 고흔이 | E31: 010-2118-2811 | F31: 1691190544@qq.com | G31: B. 피드백 및 반복 (反馈和迭代) | H31: D. 최소한의 비용과 시간 소모 (最低限度的成本和时间消耗) | I31: C. 운영적 의사결정 (运营性决策) | J31: C. 마케팅 전략 (营销策略) | K31: C. 문제해결 (问题解决) | L31: C. 착수 → 계획 → 실행 → 마무리 (启动 → 计划 → 执行 → 结束) | M31: A. 프로젝트 콘텐츠 (项目内容/产出物), B. 프로젝트 메타데이터 (项目元数据) | N31: B. 비동기적 소통 (Asynchronous Communication / 异步沟通) | O31: O (참/对) | P31: O (참/对) | Q31: =10*SUMPRODUCT(--(G31:P31<>""),--(((G31:P31=정답표!$C$2:$L$2)+(G31:P31=정답표!$C$3:$L$3))>0)) -> 90 | R31: BPR | S31: 遵循日常运营的正式化和标准化程序。 | T31: 企业间流程 | U31: 相同数据在多个部门重复存储，导致不一致。 | V31: 引入企业信息系统（EIS） | W31: 减少不必要的审批环节，从而最大限度地减少时间和资源。 | X31: 整合管理与客户的所有互动，最大限度地提高客户终身价值。 | Y31: 将业务运营整合到一个单一且一致的计算平台。 | Z31: O | AA31: O | AB31: =10*SUMPRODUCT(--(R31:AA31<>""),--(((R31:AA31=정답표!$C$4:$L$4)+(R31:AA31=정답표!$C$5:$L$5))>0)) -> 100 | AC31: 硬件、软件、数据、流程、人员 | AD31: 组织战略决定价值链，价值链决定业务流程，业务流程决定 SMIS 需求。 | AE31: 增加物质资本 | AF31: 直接销售用户数据：通过直接销售用户个人数据获取主要收入。 | AG31: 创新 (Innovation) | AH31: 指通过电子邮件、消息应用等难以追踪的渠道进行的社交分享区域，企业应在此处关注建立信任。 | AI31: 基于兴趣形成，一个用户可以同时属于多个社区。 | AJ31: 财务与会计 | AK31: O | AL31: O | AM31: =10*SUMPRODUCT(--(AC31:AL31<>""),--(((AC31:AL31=정답표!$C$6:$L$6)+(AC31:AL31=정답표!$C$7:$L$7))>0)) -> 100 | AN31: 在风险、成本和便利性之间找到适当的平衡。 | AO31: 因为将所有安全风险降至零在现实中是不可能且低效的。 | AP31: 未应用安全补丁的旧软件 | AQ31: 威胁能够访问系统或数据并造成损害的弱点。 | AR31: 将数据转换为未经授权的人无法理解的形式以进行保护的技术。 | AS31: 根据预设规则允许或阻止网络流量。 | AT31: 主要是技术部门制定和执行的技术问题。 | AU31: 定期测试备份数据是否能实际恢复非常重要。 | AV31: O | AW31: O | AX31: =10*SUMPRODUCT(--(AN31:AW31<>""),--(((AN31:AW31=정답표!$C$8:$L$8)+(AN31:AW31=정답표!$C$9:$L$9))>0)) -> 100 | AY31: 支持IT技术以实现组织目标，并将其与经营目标相结合。 | AZ31: 有效连接信息系统(IS)战略与企业经营战略。 | BA31: 根据组织的目标和优先顺序，综合考虑战略、预算和风险。 | BB31: 谁来做信息系统相关的决策，谁来承担责任？ | BC31: 综合考虑项目的战略适用性和实际可行性。 | BD31: 将组织的部分IT功能委托给外部专业公司执行。 | BE31: 安全威胁完全消除，信息安全得到加强。 | BF31: O | BG31: O | BH31: X | BI31: =10*SUMPRODUCT(--(AY31:BH31<>""),--(((AY31:BH31=정답표!$C$10:$L$10)+(AY31:BH31=정답표!$C$11:$L$11))>0)) -> 100 | BJ31: =SUM(Q31,AB31,AM31,AX31,BI31) -> 490 | BK31: =COUNT(Q31,AB31,AM31,AX31,BI31) -> 5 | BL31: =IF(QuizMatchTable[[#This Row],[분반]]=1, QuizMatchTable[[#This Row],[퀴즈합계]]/4 *0.3, QuizMatchTable[[#This Row],[퀴즈합계]]/5*0.3) -> 29.4 | BM31: 30 | BN31: 19.6 | BP31: =SUM(QuizMatchTable[[#This Row],[퀴즈점수(30)]],BM31,BN31,BO31) -> 79 | BQ31: =IF(OR(BP31="",BP31=0,BT31="결석초과"),"",COUNTIFS($B$2:$B$109,B31,$BP$2:$BP$109,">"&BP31)+1) -> 2 | BR31: A+ | BS31: 0
A32: 경영학과 | B32: 2 | C32: 20220134 | D32: 곽우봉 | E32: 010-7512-8967 | F32: 2454108044@QQ.COM | G32: B. 피드백 및 반복 (反馈和迭代) | H32: D. 최소한의 비용과 시간 소모 (最低限度的成本和时间消耗) | I32: C. 운영적 의사결정 (运营性决策) | J32: C. 마케팅 전략 (营销策略) | K32: C. 문제해결 (问题解决) | L32: C. 착수 → 계획 → 실행 → 마무리 (启动 → 计划 → 执行 → 结束) | M32: A. 프로젝트 콘텐츠 (项目内容/产出物), B. 프로젝트 메타데이터 (项目元数据) | N32: B. 비동기적 소통 (Asynchronous Communication / 异步沟通) | O32: X (거짓/错) | P32: O (참/对) | Q32: =10*SUMPRODUCT(--(G32:P32<>""),--(((G32:P32=정답표!$C$2:$L$2)+(G32:P32=정답표!$C$3:$L$3))>0)) -> 100 | R32: BPR | S32: 遵循日常运营的正式化和标准化程序。 | T32: 企业级流程 | U32: 相同数据在多个部门重复存储，导致不一致。 | V32: 引入企业信息系统（EIS） | W32: 减少不必要的审批环节，从而最大限度地减少时间和资源。 | X32: 整合管理与客户的所有互动，最大限度地提高客户终身价值。 | Y32: 将业务运营整合到一个单一且一致的计算平台。 | Z32: O | AA32: O | AB32: =10*SUMPRODUCT(--(R32:AA32<>""),--(((R32:AA32=정답표!$C$4:$L$4)+(R32:AA32=정답표!$C$5:$L$5))>0)) -> 90 | AC32: 硬件、软件、社区、流程、人员 | AD32: 价值链直接设计动态流程流以推导出 SMIS 需求。 | AE32: 增加物质资本 | AF32: 直接销售用户数据：通过直接销售用户个人数据获取主要收入。 | AG32: 创新 (Innovation) | AH32: 指通过电子邮件、消息应用等难以追踪的渠道进行的社交分享区域，企业应在此处关注建立信任。 | AI32: 基于兴趣形成，一个用户可以同时属于多个社区。 | AJ32: 财务与会计 | AK32: O | AL32: O | AM32: =10*SUMPRODUCT(--(AC32:AL32<>""),--(((AC32:AL32=정답표!$C$6:$L$6)+(AC32:AL32=정답표!$C$7:$L$7))>0)) -> 80 | AN32: 在风险、成本和便利性之间找到适当的平衡。 | AO32: 因为将所有安全风险降至零在现实中是不可能且低效的。 | AP32: 未应用安全补丁的旧软件 | AQ32: 威胁能够访问系统或数据并造成损害的弱点。 | AR32: 将数据转换为未经授权的人无法理解的形式以进行保护的技术。 | AS32: 根据预设规则允许或阻止网络流量。 | AT32: 与管理层、管理者、员工等所有组织成员的责任相关。 | AU32: 只需执行一次备份就足够了，之后不需要额外的管理。 | AV32: O | AW32: O | AX32: =10*SUMPRODUCT(--(AN32:AW32<>""),--(((AN32:AW32=정답표!$C$8:$L$8)+(AN32:AW32=정답표!$C$9:$L$9))>0)) -> 80 | AY32: 支持IT技术以实现组织目标，并将其与经营目标相结合。 | AZ32: 有效连接信息系统(IS)战略与企业经营战略。 | BA32: 根据组织的目标和优先顺序，综合考虑战略、预算和风险。 | BB32: 谁来做信息系统相关的决策，谁来承担责任？ | BC32: 综合考虑项目的战略适用性和实际可行性。 | BD32: 将组织的部分IT功能委托给外部专业公司执行。 | BE32: 安全威胁完全消除，信息安全得到加强。 | BF32: O | BG32: O | BH32: X | BI32: =10*SUMPRODUCT(--(AY32:BH32<>""),--(((AY32:BH32=정답표!$C$10:$L$10)+(AY32:BH32=정답표!$C$11:$L$11))>0)) -> 100 | BJ32: =SUM(Q32,AB32,AM32,AX32,BI32) -> 450 | BK32: =COUNT(Q32,AB32,AM32,AX32,BI32) -> 5 | BL32: =IF(QuizMatchTable[[#This Row],[분반]]=1, QuizMatchTable[[#This Row],[퀴즈합계]]/4 *0.3, QuizMatchTable[[#This Row],[퀴즈합계]]/5*0.3) -> 27 | BM32: 28 | BN32: 10 | BP32: =SUM(QuizMatchTable[[#This Row],[퀴즈점수(30)]],BM32,BN32,BO32) -> 65 | BQ32: =IF(OR(BP32="",BP32=0,BT32="결석초과"),"",COUNTIFS($B$2:$B$109,B32,$BP$2:$BP$109,">"&BP32)+1) -> 30 | BR32: F | BS32: 3
A33: 경영학과 | B33: 2 | C33: 20220139 | D33: 류개예 | E33: 010-9861-6925 | F33: 3251925645@qq.com | G33: B. 피드백 및 반복 (反馈和迭代) | H33: D. 최소한의 비용과 시간 소모 (最低限度的成本和时间消耗) | I33: C. 운영적 의사결정 (运营性决策) | J33: C. 마케팅 전략 (营销策略) | K33: C. 문제해결 (问题解决) | L33: C. 착수 → 계획 → 실행 → 마무리 (启动 → 计划 → 执行 → 结束) | M33: A. 프로젝트 콘텐츠 (项目内容/产出物), B. 프로젝트 메타데이터 (项目元数据) | N33: C. 구조적 소통 (Structured Communication / 结构化沟通) | O33: X (거짓/错) | P33: O (참/对) | Q33: =10*SUMPRODUCT(--(G33:P33<>""),--(((G33:P33=정답표!$C$2:$L$2)+(G33:P33=정답표!$C$3:$L$3))>0)) -> 90 | R33: BPR | S33: 遵循日常运营的正式化和标准化程序。 | T33: 企业间流程 | U33: 相同数据在多个部门重复存储，导致不一致。 | V33: 引入企业信息系统（EIS） | W33: 减少不必要的审批环节，从而最大限度地减少时间和资源。 | X33: 整合管理与客户的所有互动，最大限度地提高客户终身价值。 | Y33: 将业务运营整合到一个单一且一致的计算平台。 | Z33: O | AA33: O | AB33: =10*SUMPRODUCT(--(R33:AA33<>""),--(((R33:AA33=정답표!$C$4:$L$4)+(R33:AA33=정답표!$C$5:$L$5))>0)) -> 100 | AC33: 硬件、软件、数据、流程、人员 | AD33: 组织战略决定价值链，价值链决定业务流程，业务流程决定 SMIS 需求。 | AE33: 增加物质资本 | AF33: 直接销售用户数据：通过直接销售用户个人数据获取主要收入。 | AG33: 常识 (Common Sense) | AH33: 指通过电子邮件、消息应用等难以追踪的渠道进行的社交分享区域，企业应在此处关注建立信任。 | AI33: 基于兴趣形成，一个用户可以同时属于多个社区。 | AJ33: 财务与会计 | AK33: O | AL33: O | AM33: =10*SUMPRODUCT(--(AC33:AL33<>""),--(((AC33:AL33=정답표!$C$6:$L$6)+(AC33:AL33=정답표!$C$7:$L$7))>0)) -> 90 | AN33: 在风险、成本和便利性之间找到适当的平衡。 | AO33: 因为将所有安全风险降至零在现实中是不可能且低效的。 | AP33: 未应用安全补丁的旧软件 | AQ33: 威胁能够访问系统或数据并造成损害的弱点。 | AR33: 将数据转换为未经授权的人无法理解的形式以进行保护的技术。 | AS33: 根据预设规则允许或阻止网络流量。 | AT33: 主要是技术部门制定和执行的技术问题。 | AU33: 定期测试备份数据是否能实际恢复非常重要。 | AV33: O | AW33: O | AX33: =10*SUMPRODUCT(--(AN33:AW33<>""),--(((AN33:AW33=정답표!$C$8:$L$8)+(AN33:AW33=정답표!$C$9:$L$9))>0)) -> 100 | AY33: 支持IT技术以实现组织目标，并将其与经营目标相结合。 | AZ33: 有效连接信息系统(IS)战略与企业经营战略。 | BA33: 根据组织的目标和优先顺序，综合考虑战略、预算和风险。 | BB33: 谁来做信息系统相关的决策，谁来承担责任？ | BC33: 综合考虑项目的战略适用性和实际可行性。 | BD33: 将组织的部分IT功能委托给外部专业公司执行。 | BE33: 安全威胁完全消除，信息安全得到加强。 | BF33: O | BG33: O | BH33: X | BI33: =10*SUMPRODUCT(--(AY33:BH33<>""),--(((AY33:BH33=정답표!$C$10:$L$10)+(AY33:BH33=정답표!$C$11:$L$11))>0)) -> 100 | BJ33: =SUM(Q33,AB33,AM33,AX33,BI33) -> 480 | BK33: =COUNT(Q33,AB33,AM33,AX33,BI33) -> 5 | BL33: =IF(QuizMatchTable[[#This Row],[분반]]=1, QuizMatchTable[[#This Row],[퀴즈합계]]/4 *0.3, QuizMatchTable[[#This Row],[퀴즈합계]]/5*0.3) -> 28.8 | BM33: 30 | BN33: 18.39 | BP33: =SUM(QuizMatchTable[[#This Row],[퀴즈점수(30)]],BM33,BN33,BO33) -> 77.19 | BQ33: =IF(OR(BP33="",BP33=0,BT33="결석초과"),"",COUNTIFS($B$2:$B$109,B33,$BP$2:$BP$109,">"&BP33)+1) -> 12 | BR33: B+ | BS33: 0
A34: 경영학과 | B34: 2 | C34: 20220140 | D34: 류로요 | E34: 010-8379-9571 | F34: luyaoliu02@gmail.com | R34: BPR | S34: 遵循日常运营的正式化和标准化程序。 | T34: 企业间流程 | U34: 相同数据在多个部门重复存储，导致不一致。 | V34: 引入企业信息系统（EIS） | W34: 减少不必要的审批环节，从而最大限度地减少时间和资源。 | X34: 整合管理与客户的所有互动，最大限度地提高客户终身价值。 | Y34: 将业务运营整合到一个单一且一致的计算平台。 | Z34: O | AA34: O | AB34: =10*SUMPRODUCT(--(R34:AA34<>""),--(((R34:AA34=정답표!$C$4:$L$4)+(R34:AA34=정답표!$C$5:$L$5))>0)) -> 100 | AC34: 硬件、软件、数据、流程、人员 | AD34: 组织战略决定价值链，价值链决定业务流程，业务流程决定 SMIS 需求。 | AE34: 增加物质资本 | AF34: 直接销售用户数据：通过直接销售用户个人数据获取主要收入。 | AG34: 创新 (Innovation) | AH34: 指通过电子邮件、消息应用等难以追踪的渠道进行的社交分享区域，企业应在此处关注建立信任。 | AI34: 基于兴趣形成，一个用户可以同时属于多个社区。 | AJ34: 财务与会计 | AK34: O | AL34: O | AM34: =10*SUMPRODUCT(--(AC34:AL34<>""),--(((AC34:AL34=정답표!$C$6:$L$6)+(AC34:AL34=정답표!$C$7:$L$7))>0)) -> 100 | AN34: 在风险、成本和便利性之间找到适当的平衡。 | AO34: 因为将所有安全风险降至零在现实中是不可能且低效的。 | AP34: 未应用安全补丁的旧软件 | AQ34: 威胁能够访问系统或数据并造成损害的弱点。 | AR34: 将数据转换为未经授权的人无法理解的形式以进行保护的技术。 | AS34: 根据预设规则允许或阻止网络流量。 | AT34: 主要是技术部门制定和执行的技术问题。 | AU34: 定期测试备份数据是否能实际恢复非常重要。 | AV34: O | AW34: O | AX34: =10*SUMPRODUCT(--(AN34:AW34<>""),--(((AN34:AW34=정답표!$C$8:$L$8)+(AN34:AW34=정답표!$C$9:$L$9))>0)) -> 100 | AY34: 支持IT技术以实现组织目标，并将其与经营目标相结合。 | AZ34: 有效连接信息系统(IS)战略与企业经营战略。 | BA34: 根据组织的目标和优先顺序，综合考虑战略、预算和风险。 | BB34: 谁来做信息系统相关的决策，谁来承担责任？ | BC34: 综合考虑项目的战略适用性和实际可行性。 | BD34: 将组织的部分IT功能委托给外部专业公司执行。 | BE34: 安全威胁完全消除，信息安全得到加强。 | BF34: O | BG34: O | BH34: X | BI34: =10*SUMPRODUCT(--(AY34:BH34<>""),--(((AY34:BH34=정답표!$C$10:$L$10)+(AY34:BH34=정답표!$C$11:$L$11))>0)) -> 100 | BJ34: =SUM(Q34,AB34,AM34,AX34,BI34) -> 400 | BK34: =COUNT(Q34,AB34,AM34,AX34,BI34) -> 4 | BL34: =IF(QuizMatchTable[[#This Row],[분반]]=1, QuizMatchTable[[#This Row],[퀴즈합계]]/4 *0.3, QuizMatchTable[[#This Row],[퀴즈합계]]/5*0.3) -> 24 | BM34: 28 | BN34: 18.39 | BP34: =SUM(QuizMatchTable[[#This Row],[퀴즈점수(30)]],BM34,BN34,BO34) -> 70.39 | BQ34: =IF(OR(BP34="",BP34=0,BT34="결석초과"),"",COUNTIFS($B$2:$B$109,B34,$BP$2:$BP$109,">"&BP34)+1) -> 22 | BR34: F | BS34: 3
A35: 경영학과 | B35: 2 | C35: 20220141 | D35: 류명혜 | E35: 010-3952-2165 | F35: 1469098339@qq.com | G35: B. 피드백 및 반복 (反馈和迭代) | H35: D. 최소한의 비용과 시간 소모 (最低限度的成本和时间消耗) | I35: C. 운영적 의사결정 (运营性决策) | J35: C. 마케팅 전략 (营销策略) | K35: C. 문제해결 (问题解决) | L35: C. 착수 → 계획 → 실행 → 마무리 (启动 → 计划 → 执行 → 结束) | M35: A. 프로젝트 콘텐츠 (项目内容/产出物) | N35: B. 비동기적 소통 (Asynchronous Communication / 异步沟通) | O35: X (거짓/错) | P35: O (참/对) | Q35: =10*SUMPRODUCT(--(G35:P35<>""),--(((G35:P35=정답표!$C$2:$L$2)+(G35:P35=정답표!$C$3:$L$3))>0)) -> 90 | R35: BPR | S35: 遵循日常运营的正式化和标准化程序。 | T35: 企业间流程 | U35: 相同数据在多个部门重复存储，导致不一致。 | V35: 引入企业信息系统（EIS） | W35: 减少不必要的审批环节，从而最大限度地减少时间和资源。 | X35: 整合管理与客户的所有互动，最大限度地提高客户终身价值。 | Y35: 将业务运营整合到一个单一且一致的计算平台。 | Z35: O | AA35: O | AB35: =10*SUMPRODUCT(--(R35:AA35<>""),--(((R35:AA35=정답표!$C$4:$L$4)+(R35:AA35=정답표!$C$5:$L$5))>0)) -> 100 | AC35: 硬件、软件、数据、流程、人员 | AD35: 组织战略决定价值链，价值链决定业务流程，业务流程决定 SMIS 需求。 | AE35: 增加物质资本 | AF35: 直接销售用户数据：通过直接销售用户个人数据获取主要收入。 | AG35: 创新 (Innovation) | AH35: 指通过电子邮件、消息应用等难以追踪的渠道进行的社交分享区域，企业应在此处关注建立信任。 | AI35: 基于兴趣形成，一个用户可以同时属于多个社区。 | AJ35: 财务与会计 | AK35: O | AL35: O | AM35: =10*SUMPRODUCT(--(AC35:AL35<>""),--(((AC35:AL35=정답표!$C$6:$L$6)+(AC35:AL35=정답표!$C$7:$L$7))>0)) -> 100 | AN35: 在风险、成本和便利性之间找到适当的平衡。 | AO35: 因为将所有安全风险降至零在现实中是不可能且低效的。 | AP35: 未应用安全补丁的旧软件 | AQ35: 威胁能够访问系统或数据并造成损害的弱点。 | AR35: 将数据转换为未经授权的人无法理解的形式以进行保护的技术。 | AS35: 根据预设规则允许或阻止网络流量。 | AT35: 主要是技术部门制定和执行的技术问题。 | AU35: 定期测试备份数据是否能实际恢复非常重要。 | AV35: O | AW35: O | AX35: =10*SUMPRODUCT(--(AN35:AW35<>""),--(((AN35:AW35=정답표!$C$8:$L$8)+(AN35:AW35=정답표!$C$9:$L$9))>0)) -> 100 | AY35: 支持IT技术以实现组织目标，并将其与经营目标相结合。 | AZ35: 有效连接信息系统(IS)战略与企业经营战略。 | BA35: 根据组织的目标和优先顺序，综合考虑战略、预算和风险。 | BB35: 谁来做信息系统相关的决策，谁来承担责任？ | BC35: 综合考虑项目的战略适用性和实际可行性。 | BD35: 将组织的部分IT功能委托给外部专业公司执行。 | BE35: 安全威胁完全消除，信息安全得到加强。 | BF35: O | BG35: O | BH35: X | BI35: =10*SUMPRODUCT(--(AY35:BH35<>""),--(((AY35:BH35=정답표!$C$10:$L$10)+(AY35:BH35=정답표!$C$11:$L$11))>0)) -> 100 | BJ35: =SUM(Q35,AB35,AM35,AX35,BI35) -> 490 | BK35: =COUNT(Q35,AB35,AM35,AX35,BI35) -> 5 | BL35: =IF(QuizMatchTable[[#This Row],[분반]]=1, QuizMatchTable[[#This Row],[퀴즈합계]]/4 *0.3, QuizMatchTable[[#This Row],[퀴즈합계]]/5*0.3) -> 29.4 | BM35: 28 | BN35: 18.8 | BP35: =SUM(QuizMatchTable[[#This Row],[퀴즈점수(30)]],BM35,BN35,BO35) -> 76.2 | BQ35: =IF(OR(BP35="",BP35=0,BT35="결석초과"),"",COUNTIFS($B$2:$B$109,B35,$BP$2:$BP$109,">"&BP35)+1) -> 14 | BR35: B+ | BS35: 3
